Workbook

Sheet 2-7-2027
B3: Petit cash | E3: 0
B4: Cash In USD | E4: 0
B5: Oui Oui Nursery 43 X 12$ | E5: 520
E6: 0
E7: 0
E8: 0
B10: Librarie Mallah ( Oui Oui Nursery) Workshop | F10: 55
B11: Librarie Mallah ( Oui Oui Nursery) | F11: 25
B12: Librarie Mallah ( Oui Oui Nursery Paint + clay ) | F12: 23
B13: Nour Malek 4 Working H | F13: 16
B14: Angelina Khawand 4 Working H | F14: 16
B15: Nour Haybe 4 working H | F15: 16
B16: Tatyana Part Of Salay June | F16: 66
F17: 0
F18: 0
F19: 0
F20: 0
F21: 0
F22: 0
F23: 0
F24: 0
F25: 0
F26: 0
F27: 0
F28: 0
... F31: 0
B32: Total | E32: =E3+E4+E5+E6+E7+E8-F10-F12-F13-F14-F15-F16-F17-F11-F26-F27 -> 303

Sheet 3-7-2026
B3: Petit cash | E3: 0
B4: Cash In USD | E4: 238
B5: Birthday Reaven (8 Kids & 18 Adult) | E5: 434
E6: 0
E7: 0
E8: 0
B10: Le Marchet selectif (Water , Fruits, Cheese, Ice ) | F10: 100 | G10: Paid From Birthday D.P
B11: Karam Bek | F11: 48 | G11: Paid From Birthday D.P
B12: Event Megastore (Workshops) | F12: 28 | G12: Paid From Birthday D.P
B13: Librarie Mallah | F13: 22 | G13: Paid From Birthday D.P
B14: Spinneys (kitchen) | F14: 67.73 | G14: Paid From Birthday D.P
B15: Spinneys ( Workshop July 4-5) | F15: 37.27 | G15: Paid From Birthday D.P
B16: Boucherie Ziad Burger | F16: 19.09
B17: Boucherie Ziad Kebbe | F17: 56.35
B18: Borgol Basal For Kebbe | F18: 5
B19: Angelina 9 Working h | F19: 33
B20: Nour Haybe 9 Working h | F20: 42
F21: 0
F22: 0
F23: 0
F24: 0
F25: 0
F26: 0
F27: 0
F28: 0
F29: 0
F30: 0
F31: 0
B32: Total | E32: =E3+E4+E5+E6+E7+E8-F16-F17-F18-F19-F20-F21-F22-F23-F24-F25-F26-F27-F28-F29-F30-F31 -> 516.56

Sheet 4-7-2026
B3: Petit cash | E3: 16
B4: Cash In USD | E4: 751
B5: Soils Permacultura Association Lebanon | E5: 100
E6: 0
E7: 0
E8: 0
B10: KaraM Biek | F10: 60
B11: Le Marchet selectif (Birthday & Workshops ) | F11: 112
B12: Le Marchet selectif (Birthday 5-7-2026 ) | F12: 66
B13: Wooden Bakery Cake For Coffe Break | F13: 21
B14: Citern Water Toni Nehme | F14: 80
B15: Little Hands Garbage | F15: 30
B16: 3alaf For Farm | F16: 32
B17: Plumber (Saleh) | F17: 15
B18: Manakich For Little Hands | F18: 15
B19: Wooden Bakery Burger | F19: 7.5
B20: Ramel | F20: 11
B21: Assab for Garden | F21: 7
... B25: Cynthia hello 5 Working H | F25: 23
F26: 0
F27: 0
F28: 0
F29: 0
F30: 0
F31: 0
B32: Total | E32: =E3+E4+E5+E6+E7+E8-F10-F11-F12-F13-F14-F15-F16-F17-F18-F19-F20-F21-F22-F23-F24-F25-F26-F27-F28-F29-F30-F31 -> 291.61

Sheet 5-7-2026
B3: Opening Petit cash | E3: 95
B4: Walk-in Today: Cash In USD (10 Kids) | E4: 241
B5: Birthday : Michel Saade | E5: 750
B6: From Sanaa Exchange | E6: 55
E7: 0
E8: 0
B10: Le Marchet Selectif ( Fruits & Veg , Fahem,Water) | F10: 41.32
B11: Nour Haybe 4.5 Working H | F11: 24
B12: Noknok Mozarella Sticks Birthday 5-7 | F12: 22 | G12: Expenses Birthday Michel Saade Paid From D.P
B13: Storium Saliba ( Birthday & Bar ) | F13: 28.79 | G13: Expenses Birthday Michel Saade Paid From D.P
B14: Spinneys Birthday Food & Supplies | F14: 171 | G14: Expenses Birthday Michel Saade Paid From D.P
B15: Event Megastore ( Birthday Workshops ) | F15: 79.31 | G15: Expenses Birthday Michel Saade Paid From D.P
B16: Nancy Old Blance (Sent Via Wish BY Sanaa) | F16: 66
B17: Miro Advance Full July Salary | F17: 600
B18: Nour Malek Face Painting | F18: 15
B19: Nour Malek 9 Working H + 8$ Old Balance | F19: 44
B20: Angelina 9 Working H | F20: 30
B21: Cynythia 9 Working H | F21: 35
F22: 0
F23: 0
F24: 0
F25: 0
F26: 0
F27: 0
F28: 0
F29: 0
F30: 0
F31: 0
B32: Total | E32: =E3+E4+E5+E6+E7+E8-F10-F11-F16-F17-F18-F19-F20-F21-F22-F23-F24-F25-F26-F27-F28-F29-F30-F31 -> 285.68

Sheet 8-7-2026
B3: Opening Petit cash | E3: 0
B4: Walk-in Today: Cash In USD (10 Kids) | E4: 0
B5: Birthday : Dina Bekdach | E5: 625
B6: Garderie Bebe Sucre 60 kids | E6: 760
E7: 0
E8: 0
B10: Kafta & Taouk For Birthday | F10: 29 | G10: Expenses Birthday Dina Bekdach Paid From D.P
B11: Mallah Librarie | F11: 60 | G11: Expenses Birthday Dina Bekdach Paid From D.P | J11: 30
B12: Storium Kitchen & Hygiene For Birthday | F12: 79 | G12: Expenses Birthday Dina Bekdach Paid From D.P | J12: 78
F13: 0 | G13: Expenses Birthday Dina Bekdach Paid From D.P
F14: 0 | G14: Expenses Birthday Dina Bekdach Paid From D.P
B15: Nour malek Visit Bebe Sucre | F15: 30
B16: Returned To Sanaa From Exchange | F16: 65
B17: Cynthia 4 Working H | F17: 24
B18: Nour Haybe Nursery Visite | F18: 54
B19: Moteur June 2026 | F19: 300
B20: Panino | F20: 6.74
B21: Kassab Rabet For Garden | F21: 15
F22: 0
F23: 0
F24: 0
F25: 0
F26: 0
F27: 0
F28: 0
F29: 0
F30: 0
F31: 0
B32: Total | E32: =E3+E4+E5+E6+E7+E8-F15-F16-F17-F18-F19-F20-F21 -> 890.26

Sheet 9-7-2026
B3: Opening Petit cash | E3: 0
B4: Walk-in Today: Cash In USD | E4: 0
B5: Birthday Down Payment: Carine Bejani | E5: 300
B6: Garderie Bebe Sucre 44 kids | E6: 528
E7: 0
E8: 0
B10: Le Marche Selectif | F10: 82
B11: Nour Malek | F11: 16
B12: Angelina | F12: 24
B13: Nour Haybe | F13: 22
F14: 0
F15: 0
F16: 0
F17: 0
F18: 0
F19: 0
F20: 0
F21: 0
F22: 0
F23: 0
F24: 0
F25: 0
... F31: 0
B32: Total | E32: =E3+E4+E5+E6+E7+E8-F15-F16-F17-F18-F19-F20-F21-F10-F11-F12-F13 -> 684

Sheet 10-7-2026
B3: Opening Petit cash | E3: 0
B4: Walk-in Today: Cash In USD (1 Kid) | E4: 20
B5: Birthday : Vanessa Moussan | E5: 755
B6: Garderie Maisonette Des petits Minous 32 kid | E6: 384
E7: 0
E8: 0
B10: Le Marche Selectif | F10: 146 | G10: Expenses Birthday Greta Fadel Paid From D.P
B11: karam Beik | F11: 55 | G11: Expenses Birthday Greta Fadel Paid From D.P
B12: Spinneys | F12: 188 | G12: Expenses Birthday Vanessa Moussan Paid From D.P
B13: Boucherie Ziad Kebbe Burger for Birthday 10/11/12 | F13: 170 | G13: Expenses Birthday Vanessa Moussan Paid From D.P
F14: 0 | G14: Expenses Birthday Vanessa Moussan Paid From D.P
F15: 0
B16: Fairco International | F16: 40.9
B17: Maliks (Print Out ) | F17: 8.98
B18: Returne To Sara Exchange | F18: 10
B19: Citern water | F19: 88
B20: Panino | F20: 21
B21: Pharmacie Chantal | F21: 5
B22: Nour Haybe | F22: 38
B23: Nour Malek (Face Painting & Working H) | F23: 40
F24: 0
F25: 0
F26: 0
F27: 0
F28: 0
F29: 0
F30: 0
F31: 0
B32: Total | E32: =E3+E4+E5+E6+E7+E8-F15-F16-F17-F18-F19-F20-F21-F22-F23 -> 907.12

Sheet 11-7-2026
B3: Opening Petit cash | E3: 0
B4: Walk-in Today: Cash In USD (2 Kid | E4: 453
B5: Birthday : Carine Fadel | E5: 1335
E6: 0
E7: 0
E8: 0
B10: Le Marche Selectif | F10: 108 | G10: Expenses Birthday Clara Khachan Paid From D.P
B11: karam Beik | F11: 63 | G11: Expenses Birthday Clara Khachan Paid From D.P
B12: Storium | F12: 24 | G12: Expenses Birthday Clara Khachan Paid From D.P
B13: Boucherie Ziad Kebbe Burger for Birthday 12 | F13: 38 | G13: Expenses Birthday Clara Khachan Paid From D.P
F14: 0
F15: 0
B16: Ets Melhem Yamine Marawih For Garden | F16: 160
B17: Youssef Malek Tabali For Garden | F17: 120
B18: Nour Malek Face Painting & working H | F18: 52
B19: Angelina | F19: 33
B20: Nour Haybe | F20: 36
F21: 0
F22: 0
F23: 0
F24: 0
F25: 0
F26: 0
F27: 0
F28: 0
F29: 0
F30: 0
F31: 0
B32: Total | E32: =E3+E4+E5+E6+E7+E8-F15-F16-F17-F18-F19-F20 -> 1387

Sheet 12-7-2026
B3: Opening Petit cash | E3: 0
B4: Walk-in Today: Cash In USD ( 9 Kids) | E4: 369.5
B5: Birthday : Clara Khachan | E5: 556
E6: 0
E7: 0
E8: 0
B10: Storium | F10: 56 | G10: Expenses Birthday Clara Khachan Paid From D.P
F11: 0
B12: Nour Haybe | F12: 38
B13: Nour Malek | F13: 32
B14: Boucherie Ziad Mafroume & Burgers | F14: 50
B15: Prodel Disposables | F15: 160
B16: Cynthia Helo | F16: 25
F17: 0
F18: 0
F19: 0
F20: 0
F21: 0
F22: 0
F23: 0
F24: 0
F25: 0
F26: 0
F27: 0
B28: Total | E28: =E3+E4+E5+E6+E7+E8-F11-F12-F13-F14-F15-F16-F17-F18 -> 620.5

Sheet 15-7-2026
B3: Opening Petit cash | E3: 0
B4: Walk-in Today: Cash In USD | E4: 0
B5: Garderie Le Cocon 43 kids | E5: 516
B6: Maria Abi Nader D.P Birthday 27/7 | E6: 300
B7: Lara El Khoury D.P Birthday 25/7 | E7: 300
E8: 0
B10: Nour Malek | F10: 11
F11: 0
F12: 0
F13: 0
F14: 0
F15: 0
F16: 0
F17: 0
F18: 0
F19: 0
F20: 0
F21: 0
F22: 0
... F27: 0
B28: Total | E28: =E3+E4+E5+E6+E7+E8-F11-F12-F13-F14-F15-F16-F17-F18 -> 1116

Sheet 17-7-2026
B3: Opening Petit cash | E3: 0
B4: Walk-in Today: Cash In USD | E4: 284
B5: Alex Khoury (Katherine) | E5: 520
B6: Marianne Tamim D.P Birthday 24/7 | E6: 300
E7: 0
E8: 0
B10: EDL Little Hands | F10: 52
B11: Citern water For Little Hands | F11: 80
B12: Allaf For Farm | F12: 98
B13: Karam Beik | F13: 53
B14: Event Megastore | F14: 5.1
B15: Lteif Market | F15: 9.17
B16: zaatar Manakich | F16: 18
B17: spray Rash | F17: 7
B18: Nour Haybe | F18: 26
B19: Nour Malek Face Painting | F19: 30
B20: Cynthia Hello | F20: 26
B21: Spinneys Birthday | F21: 300 | G21: Expenses Birthday Alex Khoury Paid From D.P
F22: 0
F23: 0
F24: 0
F25: 0
F26: 0
F27: 0
B28: Total | E28: =E3+E4+E5+E6+E7+E8-F11-F12-F13-F14-F15-F16-F17-F18-F10-F19-F20 -> 699.73

Sheet 18-7--2026
B3: Opening Petit cash | E3: 0
B4: Walk-in Today: Cash In USD | E4: 330
B5: Cynthia Mattar | E5: 1150 | G5: N.B (D.P 300 $ of this Birthday Used For May Salaries)
B6: From Uyoussef Exchange | E6: 50
E7: 0
E8: 0
B10: Le Marchet Selectif | F10: 200
B11: Karam Bek | F11: 75
B12: spinneys | F12: 51
B13: spinneys | F13: 20
B14: Storium | F14: 20
B15: firco International ( Workshop birthday ) | F15: 104
B16: Spinneys | F16: 75
B17: Balkis | F17: 22.5
B18: Mallah Clay | F18: 15
B19: Mallah Printing Clay Workshops | F19: 77
B20: Disposbles | F20: 135
B21: Luigi, Boucherie Ziad | F21: 200 | G21: Expenses D.P Birthday Heather 200 $ Sunday
B22: Cynthia Hello | F22: 31
B23: Luccianna | F23: 21
F24: 0
F25: 0
F26: 0
F27: 0
B28: Total | E28: =E3+E4+E5+E6+E7+E8-F11-F12-F13-F14-F15-F16-F17-F18-F10-F19-F20-F22-F23 -> 683.5

Sheet 19-72026
B3: Opening Petit cash | E3: 0
B4: Walk-in Today: Cash In USD | E4: 77
B5: Heather | E5: 525 | G5: Sent Via Wish To Sanaa
E6: 0
E7: 0
E8: 0
B10: Nour Haybe | F10: 22
B11: Noura Malek | F11: 20
B12: nancy hello | F12: 31
F13: 0
F14: 0
F15: 0
F16: 0
F17: 0
F18: 0
F19: 0
F20: 0
F21: 0
F22: 0
F23: 0
F24: 0
... F27: 0
B28: Total | E28: =E3+E4+E5+E6+E7+E8-F11-F12-F13-F14-F15-F16-F17-F18-F10-F19-F20-F22-F23 -> 529

Sheet 22-7-2026
B3: Opening Petit cash | E3: 0
B4: Walk-in Today: Cash In USD | E4: 0
B5: Rabieh Summer Camp | E5: 660
B6: laura Ajamian 31/July Birthday D.P | E6: 100
E7: 0
E8: 0
B10: Event Megastore | F10: 27.3
B11: Librarie Mallah | F11: 29.88
B12: le marchet Selectif (Old Invoices) | F12: 160
B13: Spray Hacharat | F13: 1.22
B14: Ramel Mgharbal | F14: 26
B15: Zaatar | F15: 6.8
B16: Internet Little Hands | F16: 100
B17: Thaer | F17: 37
B18: Ghaz Little Hands | F18: 48
B19: Return Tou Youssef | F19: 50
F20: 0
F21: 0
F22: 0
F23: 0
F24: 0
F25: 0
F26: 0
F27: 0
B28: Total | E28: =E3+E4+E5+E6+E7+E8-F11-F12-F13-F14-F15-F16-F17-F18-F10-F19-F20-F22-F23 -> 273.8

Sheet 24-7-2026
B3: Opening Petit cash | E3: 73
B4: Walk-in Today: Cash In USD | E4: 228
B5: Birthday Marianne Tamim | E5: 450
E6: 0
E7: 0
E8: 0
B10: Angelina Working H | F10: 21
B11: Nour Haybe | F11: 26
B12: Mariam Fegir | F12: 15
B13: Spinneys Food supplies For Birthdays 24-25-26 | F13: 400 | G13: From Depposit Miriam Tamim & Lara Khoury
B14: Event Megastore | F14: 78.54 | G14: From Depposit Miriam Tamim & Lara Khoury
B15: Event Megastore | F15: 18 | G15: From Depposit Miriam Tamim & Lara Khoury
B16: Le Charcutier | F16: 46.22 | G16: From Depposit Miriam Tamim & Lara Khoury
B17: Librarie Mallah | F17: 47.4 | G17: From Depposit Miriam Tamim & Lara Khoury
B18: Le Marchet Selectif | F18: 100
F19: 0
F20: 0
F21: 0
F22: 0
F23: 0
F24: 0
F25: 0
F26: 0
F27: 0
B28: Total | E28: =E3+E4+E5+E6+E7+E8-F11-F12-F18-F10-F19-F20-F22-F23 -> 589

Sheet 25-7-2026
B3: Opening Petit cash | E3: 39
B4: Walk-in Today: Cash In USD | E4: 191
B5: Birthday Lara Khoury | E5: 650
E6: 0
E7: 0
E8: 0
B10: Thaer | F10: 100 | H10: 35
B11: Citern water | F11: 80 | H11: 38
B12: Nour Hyabe | F12: 38
B13: Le Marchet Selectif | F13: 195 | G13: From Depposit
B14: Amal Burgers For 2 days | F14: 125 | G14: From Depposit
B15: karam Bake For 2 Days | F15: 162 | G15: From Depposit
B16: Cynthia Hello | F16: 35
B17: karam bake Old Inv | F17: 49
F18: 0
F19: 0
F20: 0
F21: 0
F22: 0
F23: 0
F24: 0
F25: 0
F26: 0
F27: 0
B28: Total | E28: =E3+E4+E5+E6+E7+E8-F11-F12-F18-F10-F19-F20-F22-F23-F16-F17 -> 578

Sheet 26-7-2026
B3: Opening Petit cash | E3: 75
B4: Walk-in Today: Cash In USD | E4: 0
B5: Birthday Lara Khoury | E5: 1690
E6: 0
E7: 0
E8: 0
B10: Le amrchet Selectif | F10: 150
B11: Geryes Malek | F11: 200
B12: Spinneys | F12: 160
B13: Kitchen Tools | F13: 165
B14: Lara Cleaning Extra 5 H | F14: 25
B15: Nour Malek | F15: 22
B16: Lucciana | F16: 17
B17: Cynthia Hello | F17: 25
B18: Nour Haybe | F18: 28
F19: 0
F20: 0
F21: 0
F22: 0
F23: 0
F24: 0
F25: 0
F26: 0
F27: 0
B28: Total | E28: =E3+E4+E5+E6+E7+E8-F10-F11-F12-F13-F14-F15-F16-F17-F18 -> 973

Sheet 27-7-2026
B3: Opening Petit cash | E3: 0
B4: Walk-in Today: Cash In USD | E4: 0
B5: Birthday Athenas | E5: 1477
E6: 0
E7: 0
E8: 0
B10: Le Marchet Selectif | F10: 112
B11: Karam Bake | F11: 75
B12: Fairco | F12: 16
B13: Boucherie Ziad 4 days Birthday’s | F13: 118
B14: Fairco | F14: 26
B15: Firas ( Youssef) | F15: 200
B16: Nour Haybe | F16: 22
B17: Mariam | F17: 18
B18: Amal Asdvance Salary August | F18: 100
B19: Fady Tanjeed (11*12$) +36$ | F19: 168
B20: Desposables | F20: 50
F21: 0
F22: 0
F23: 0
F24: 0
F25: 0
F26: 0
F27: 0
B28: Total | E28: =E3+E4+E5+E6+E7+E8-F10-F11-F12-F13-F14-F15-F16-F17-F18-F19-F20 -> 572

Sheet 28-7-2026
B3: Opening Petit cash | E3: 0
B4: Walk-in Today: Cash In USD | E4: 0
B5: Dent De Lait Nursery | E5: 204
B6: Exchange From marleine ( 25$ karam Bake Yesterday & 6 dent de Lait ) | E6: 31
E7: 0
E8: 0
B10: Le Marchet Selectif | F10: 30
B11: Thaer (Orange) | F11: 20
F12: 0
F13: 0
F14: 0
F15: 0
F16: 0
F17: 0
F18: 0
F19: 0
F20: 0
F21: 0
F22: 0
F23: 0
... F27: 0
B28: Total | E28: =E3+E4+E5+E6+E7+E8-F10-F11-F12-F13-F14-F15-F16-F17-F18-F19-F20 -> 185

Sheet 29-7-2026
B3: Opening Petit cash | E3: 0
B4: Walk-in Today: Cash In USD | E4: 0
B5: Birthday Carine Ghatas | E5: 950
E6: 0
E7: 0
E8: 0
B10: Fairco International | F10: 83.36 | G10: From Birthday Deposit Carine Ghatas
B11: Storium | F11: 144.66 | G11: From Birthday Deposit Carine Ghatas
B12: Spinneys | F12: 69 | G12: From Birthday Deposit Carine Ghatas
B13: Boucherie Ziad | F13: 75
B14: Nour Malek | F14: 25
B15: Lucciana | F15: 21
B16: Nour Haybe | F16: 26
B17: Firas (Youssef) | F17: 20
B18: Exchange Returned to Marleine | F18: 30
F19: 0
F20: 0
F21: 0
F22: 0
F23: 0
F24: 0
F25: 0
F26: 0
F27: 0
B28: Total | E28: =E3+E4+E5+E6+E7+E8-F13-F14-F15-F16-F17-F18-F19-F20 -> 753

Sheet 30-7-2026
B3: Opening Petit cash | E3: 0
B4: Walk-in Today: Cash In USD | E4: 0
B5: Dent De Lait | E5: 228
E6: 0
E7: 0
E8: 0
B10: Panino Bakery | F10: 6.74
B11: Asab For Garden | F11: 15
B12: Aalaf | F12: 76
F13: 0
F14: 0
F15: 0
F16: 0
F17: 0
F18: 0
F19: 0
F20: 0
F21: 0
F22: 0
F23: 0
F24: 0
... F27: 0
B28: Total | E28: =E3+E4+E5+E6+E7+E8-F13-F14-F15-F16-F17-F18-F19-F20-F10-F11-F12 -> 130.26

Sheet 31-7-2026
B3: Opening Petit cash | E3: 150
B4: Walk-in Today: Cash In USD | E4: 166
B5: Le Petit Paradis | E5: 336
B6: Yara Haber D.P Birthday 28-8 | E6: 300
B7: Mia Ajamian Birthday | E7: 185
E8: 0
B10: Nour Haybe | F10: 22
B11: Cynthia Hello | F11: 20
B12: Le Marchet Selectif (Birthday 29-7 & Birthday 31-7) | F12: 104
B13: Nour Malek | F13: 24
B14: Lucciana | F14: 20
B15: Librarie Mallah | F15: 95 | G15: From Depposit Kylies & Laura Ajamian
B16: Spinneys | F16: 35 | G16: From Depposit Kylies & Laura Ajamian
B17: Spinneys | F17: 64 | G17: From Depposit Kylies & Laura Ajamian
F18: 0
F19: 0
F20: 0
F21: 0
F22: 0
F23: 0
F24: 0
F25: 0
F26: 0
F27: 0
B28: Total | E28: =E3+E4+E5+E6+E7+E8-F13-F14-F18-F19-F20-F10-F11-F12 -> 947

Sheet Total July
B1: Description | C1: In$ | D1: Exp $ | E1: Invoice Already Paid From D.P Birthday | F1: Cash With sanaa From sales | G1: Down Payment Birthday & Event | H1: Total$
A2: 1-7-2026 | B2: Remaining Cash From June 2026 | C2: 450 | H2: =C2 -> 450
B3: Remaining Cash From Birthday D.P June | G3: 2380 | H3: =H2+C3-D3 -> 450
A4: 2-7-2026 | B4: Librarie Mallah ( Oui Oui Nursery) Workshop | D4: 55 | H4: =H3+C4-D4 -> 395
B5: Librarie Mallah ( Oui Oui Nursery) | D5: 25 | H5: =H4+C5-D5 -> 370
B6: Librarie Mallah ( Oui Oui Nursery Paint + clay ) | D6: 23 | H6: =H5+C6-D6 -> 347
B7: Nour Malek 4 Working H | D7: 16 | H7: =H6+C7-D7 -> 331
B8: Angelina Khawand 4 Working H | D8: 16 | H8: =H7+C8-D8 -> 315
B9: Nour Haybe 4 working H | D9: 16 | H9: =H8+C9-D9 -> 299
B10: Tatyana Part Of Salay June | D10: 66 | H10: =H9+C10-D10 -> 233
B11: Oui Oui Nursery 43 X 12$ | C11: 520 | H11: =H10+C11-D11 -> 753
B12: Cash Flow (Sanaa) | F12: 300 | H12: =H11+C12-D12 -> 753
A13: 3-7-2026 | B13: Le Marchet selectif (Water , Fruits, Cheese, Ice ) | E13: 100 | H13: =H12+C13-D13 -> 753
B14: Karam Bek | E14: 48 | H14: =H13+C14-D14 -> 753
B15: Event Megastore (Workshops) | E15: 28 | H15: =H14+C15-D15 -> 753
B16: Librarie Mallah | E16: 22 | H16: =H15+C16-D16 -> 753
B17: Spinneys (kitchen) | E17: 67.73 | H17: =H16+C17-D17 -> 753
B18: Spinneys ( Workshop July 4-5) | E18: 37.27 | H18: =H17+C18-D18 -> 753
B19: Boucherie Ziad Burger | D19: 19.09 | E19: 0 | H19: =H18+C19-D19 -> 733.91
B20: Boucherie Ziad Kebbe | D20: 56.35 | E20: 0 | H20: =H19+C20-D20 -> 677.56
B21: Borgol Basal For Kebbe | D21: 5 | H21: =H20+C21-D21 -> 672.56
B22: Angelina 9 Working h | D22: 33 | H22: =H21+C22-D22 -> 639.56
B23: Nour Haybe 9 Working h | D23: 42 | H23: =H22+C23-D23 -> 597.56
B24: Cash In 4-7-2026 | C24: 238 | H24: =H23+C24-D24 -> 835.56
B25: Birthday Reaven 3-7-2026 | C25: 434 | H25: =H24+C25-D25 -> 1269.56
B26: Cash Flow (Sanaa) | F26: 500 | H26: =H25+C26-D26 -> 1269.56
A27: 4-7-2026 | B27: Cash In 4-7-2026 | C27: ='4-7-2026'!E4 -> 751 | H27: =H26+C27-D27 -> 2020.56
B28: Soils Permacultura Association Lebanon | C28: ='4-7-2026'!E5 -> 100 | H28: =H27+C28-D28 -> 2120.56
B29: KaraM Biek | D29: 60 | H29: =H28+C29-D29 -> 2060.56
B30: Le Marchet selectif (Birthday & Workshops ) | D30: 112 | H30: =H29+C30-D30 -> 1948.56
B31: Le Marchet selectif (Birthday 5-7-2026 ) | D31: 66 | H31: =H30+C31-D31 -> 1882.56
B32: Wooden Bakery Cake For Coffe Break | D32: 21 | H32: =H31+C32-D32 -> 1861.56
B33: Citern Water Toni Nehme | D33: 80 | H33: =H32+C33-D33 -> 1781.56
B34: Little Hands Garbage | D34: 30 | H34: =H33+C34-D34 -> 1751.56
B35: 3alaf For Farm | D35: 32 | H35: =H34+C35-D35 -> 1719.56
B36: Plumber (Saleh) | D36: 15 | H36: =H35+C36-D36 -> 1704.56
B37: Manakich For Little Hands | D37: 15 | H37: =H36+C37-D37 -> 1689.56
B38: Wooden Bakery Burger | D38: 7.5 | H38: =H37+C38-D38 -> 1682.06
B39: Ramel | D39: 11 | H39: =H38+C39-D39 -> 1671.06
B40: Assab for Garden | D40: 7 | H40: =H39+C40-D40 -> 1664.06
...
