Workbook

Sheet Daily Profitability
A1: M - July & August Daily Profitability | X1: Month List | Y1: Activity List | Z1: Category List | AA1: Expense Type List | AB1: Supplier List | AC1: Revenue Stream List
X2: All | Y2: All | Z2: All | AA2: All | AB2: All | AC2: All
A3: Month | B3: All | D3: Activity | E3: All | G3: Expense Category | H3: Food & Beverage | J3: Expense Type | K3: All | M3: Supplier | N3: All | P3: Revenue Stream | Q3: All | X3: July 2026 | Y3: Birthday | Z3: Cleaning & Waste | AA3: Cleaning & Sanitation | AB3: Agaric | AC3: Walk-in
A4: Total Income | C4: Expenses | E4: Revenue | G4: Net Benefit | I4: Net Margin | X4: August 2026 | Y4: Event | Z4: Disposables & Packaging | AA4: Decoration & Workshop Materials | AB4: Asab & Tools For Garden | AC4: Colonie
A5: =B13 -> 32749 | C5: =C13 -> 6652.6783 | E5: =D13 -> 32749 | G5: =E13 -> 26096.322 | I5: =F13 -> 0.79685858 | Y5: General Operations | Z5: Equipment & Tools | AA5: Electricity | AB5: Boucherie Ziad | AC5: Birthday
Y6: Nursery Visit | Z6: Food & Beverage | AA6: Food & Beverage | AB6: Chebl Bou Akl
Y7: Unspecified | Z7: Garden & Grounds | AA7: Garden & Landscaping | AB7: Disposable
Y8: Walk-in | Z8: Health & Safety | AA8: Internet | AB8: Divers
A9: Monthly Summary | G9: Definitions & Source Note | Y9: Workshop | Z9: Unclassified | AA9: Kitchen Equipment | AB9: EDL
A10: Month | B10: Total Income | C10: Expenses | D10: Revenue | E10: Net Benefit | F10: Net Margin | G10: Month controls the visible dates and selected totals. Revenue Stream filters income and Revenue. Activity, Expense Category, Expense Type and Supplier filter Expenses. The revenue and expense filters are independent. Total Income = Walk-in + Colonie + Birthday for the selected stream. Source Daily Expenses is blank, so Income and Revenue match. Net Benefit = Revenue − master expenses. July 1 has no income-source row and remains marked as missing. | Z10: Utilities & Office | AA10: Maintenance | AB10: Ets Melhem Yamine & Sons
A11: =IF($B$3="All","July 2026",$B$3) -> July 2026 | B11: =SUM(E17:E47) -> 19095 | C11: =SUM(F17:F47) -> 4921.815 | D11: =SUM(G17:G47) -> 19095 | E11: =D11-C11 -> 14173.185 | F11: =IFERROR(E11/D11,0) -> 0.74224588 | Z11: Workshop & Decoration Supplies | AA11: Other / Office | AB11: Event Megastore
A12: =IF($B$3="All","August 2026","") -> August 2026 | B12: =IF($B$3="All",SUM(E48:E78),"") -> 13654 | C12: =IF($B$3="All",SUM(F48:F78),"") -> 1730.8633 | D12: =IF($B$3="All",SUM(G48:G78),"") -> 13654 | E12: =IF(A12="","",D12-C12) -> 11923.137 | F12: =IF(A12="","",IFERROR(E12/D12,0)) -> 0.87323398 | AA12: Packaging & Disposables | AB12: Fadi
A13: Selected Total | B13: =SUM(B11:B12) -> 32749 | C13: =SUM(C11:C12) -> 6652.6783 | D13: =SUM(D11:D12) -> 32749 | E13: =SUM(E11:E12) -> 26096.322 | F13: =IFERROR(E13/D13,0) -> 0.79685858 | AA13: Waste Removal | AB13: Fairco International
AA14: Water | AB14: Forn Zakhia
A15: Daily Unified Table | AB15: Fresh & More
A16: Date | B16: Walk-in Income | C16: Colonie Income | D16: Birthday Income | E16: Total Income | F16: Expenses | G16: Revenue | H16: Net Benefit | I16: Net Margin | J16: Source Status | AB16: Imaco
A17: =IF($B$3="All",46204,IF(0<31,IF($B$3="July 2026",46204,46235)+0,"")) -> 46204 | B17: =IF(A17="","",IF(COUNTIFS('Income Source'!$B$5:$B$65,A17)=0,"",IF(OR($Q$3="All",$Q$3="Walk-in"),SUMIFS('Income Source'!$C$5:$C$65,'Income Source'!$B$5:$B$65,A17),0))) | C17: =IF(A17="","",IF(COUNTIFS('Income Source'!$B$5:$B$65,A17)=0,"",IF(OR($Q$3="All",$Q$3="Colonie"),SUMIFS('Income Source'!$D$5:$D$65,'Income Source'!$B$5:$B$65,A17),0))) | D17: =IF(A17="","",IF(COUNTIFS('Income Source'!$B$5:$B$65,A17)=0,"",IF(OR($Q$3="All",$Q$3="Birthday"),SUMIFS('Income Source'!$E$5:$E$65,'Income Source'!$B$5:$B$65,A17),0))) | E17: =IF(A17="","",IF(COUNTIFS('Income Source'!$B$5:$B$65,A17)=0,"",SUM(B17:D17))) | F17: =IF(A17="","",SUMIFS('Expense Source'!$M$5:$M$178,'Expense Source'!$D$5:$D$178,A17,'Expense Source'!$U$5:$U$178,1)) -> 0 | G17: =IF(A17="","",IF(COUNTIFS('Income Source'!$B$5:$B$65,A17)=0,"",IF($Q$3="All",SUMIFS('Income Source'!$G$5:$G$65,'Income Source'!$B$5:$B$65,A17),SUM(B17:D17)))) | H17: =IF(A17="","",IF(COUNTIFS('Income Source'!$B$5:$B$65,A17)=0,"",G17-F17)) | I17: =IF(OR(A17="",COUNTIFS('Income Source'!$B$5:$B$65,A17)=0,G17=0),"",H17/G17) | J17: =IF(A17="","",IF(COUNTIFS('Income Source'!$B$5:$B$65,A17)=0,"Revenue source missing",IF(ABS(E17-G17)>0.005,"Income/revenue mismatch","OK"))) -> Revenue source missing | AB17: Internet
A18: =IF($B$3="All",46205,IF(1<31,IF($B$3="July 2026",46204,46235)+1,"")) -> 46205 | B18: =IF(A18="","",IF(COUNTIFS('Income Source'!$B$5:$B$65,A18)=0,"",IF(OR($Q$3="All",$Q$3="Walk-in"),SUMIFS('Income Source'!$C$5:$C$65,'Income Source'!$B$5:$B$65,A18),0))) -> 0 | C18: =IF(A18="","",IF(COUNTIFS('Income Source'!$B$5:$B$65,A18)=0,"",IF(OR($Q$3="All",$Q$3="Colonie"),SUMIFS('Income Source'!$D$5:$D$65,'Income Source'!$B$5:$B$65,A18),0))) -> 520 | D18: =IF(A18="","",IF(COUNTIFS('Income Source'!$B$5:$B$65,A18)=0,"",IF(OR($Q$3="All",$Q$3="Birthday"),SUMIFS('Income Source'!$E$5:$E$65,'Income Source'!$B$5:$B$65,A18),0))) -> 0 | E18: =IF(A18="","",IF(COUNTIFS('Income Source'!$B$5:$B$65,A18)=0,"",SUM(B18:D18))) -> 520 | F18: =IF(A18="","",SUMIFS('Expense Source'!$M$5:$M$178,'Expense Source'!$D$5:$D$178,A18,'Expense Source'!$U$5:$U$178,1)) -> 0 | G18: =IF(A18="","",IF(COUNTIFS('Income Source'!$B$5:$B$65,A18)=0,"",IF($Q$3="All",SUMIFS('Income Source'!$G$5:$G$65,'Income Source'!$B$5:$B$65,A18),SUM(B18:D18)))) -> 520 | H18: =IF(A18="","",IF(COUNTIFS('Income Source'!$B$5:$B$65,A18)=0,"",G18-F18)) -> 520 | I18: =IF(OR(A18="",COUNTIFS('Income Source'!$B$5:$B$65,A18)=0,G18=0),"",H18/G18) -> 1 | J18: =IF(A18="","",IF(COUNTIFS('Income Source'!$B$5:$B$65,A18)=0,"Revenue source missing",IF(ABS(E18-G18)>0.005,"Income/revenue mismatch","OK"))) -> OK | AB18: Jamil Rezk
A19: =IF($B$3="All",46206,IF(2<31,IF($B$3="July 2026",46204,46235)+2,"")) -> 46206 | B19: =IF(A19="","",IF(COUNTIFS('Income Source'!$B$5:$B$65,A19)=0,"",IF(OR($Q$3="All",$Q$3="Walk-in"),SUMIFS('Income Source'!$C$5:$C$65,'Income Source'!$B$5:$B$65,A19),0))) -> 0 | C19: =IF(A19="","",IF(COUNTIFS('Income Source'!$B$5:$B$65,A19)=0,"",IF(OR($Q$3="All",$Q$3="Colonie"),SUMIFS('Income Source'!$D$5:$D$65,'Income Source'!$B$5:$B$65,A19),0))) -> 0 | D19: =IF(A19="","",IF(COUNTIFS('Income Source'!$B$5:$B$65,A19)=0,"",IF(OR($Q$3="All",$Q$3="Birthday"),SUMIFS('Income Source'!$E$5:$E$65,'Income Source'!$B$5:$B$65,A19),0))) -> 434 | E19: =IF(A19="","",IF(COUNTIFS('Income Source'!$B$5:$B$65,A19)=0,"",SUM(B19:D19))) -> 434 | F19: =IF(A19="","",SUMIFS('Expense Source'!$M$5:$M$178,'Expense Source'!$D$5:$D$178,A19,'Expense Source'!$U$5:$U$178,1)) -> 0 | G19: =IF(A19="","",IF(COUNTIFS('Income Source'!$B$5:$B$65,A19)=0,"",IF($Q$3="All",SUMIFS('Income Source'!$G$5:$G$65,'Income Source'!$B$5:$B$65,A19),SUM(B19:D19)))) -> 434 | H19: =IF(A19="","",IF(COUNTIFS('Income Source'!$B$5:$B$65,A19)=0,"",G19-F19)) -> 434 | I19: =IF(OR(A19="",COUNTIFS('Income Source'!$B$5:$B$65,A19)=0,G19=0),"",H19/G19) -> 1 | J19: =IF(A19="","",IF(COUNTIFS('Income Source'!$B$5:$B$65,A19)=0,"Revenue source missing",IF(ABS(E19-G19)>0.005,"Income/revenue mismatch","OK"))) -> OK | AB19: Joe Market
A20: =IF($B$3="All",46207,IF(3<31,IF($B$3="July 2026",46204,46235)+3,"")) -> 46207 | B20: =IF(A20="","",IF(COUNTIFS('Income Source'!$B$5:$B$65,A20)=0,"",IF(OR($Q$3="All",$Q$3="Walk-in"),SUMIFS('Income Source'!$C$5:$C$65,'Income Source'!$B$5:$B$65,A20),0))) -> 238 | C20: =IF(A20="","",IF(COUNTIFS('Income Source'!$B$5:$B$65,A20)=0,"",IF(OR($Q$3="All",$Q$3="Colonie"),SUMIFS('Income Source'!$D$5:$D$65,'Income Source'!$B$5:$B$65,A20),0))) -> 100 | D20: =IF(A20="","",IF(COUNTIFS('Income Source'!$B$5:$B$65,A20)=0,"",IF(OR($Q$3="All",$Q$3="Birthday"),SUMIFS('Income Source'!$E$5:$E$65,'Income Source'!$B$5:$B$65,A20),0))) -> 751 | E20: =IF(A20="","",IF(COUNTIFS('Income Source'!$B$5:$B$65,A20)=0,"",SUM(B20:D20))) -> 1089 | F20: =IF(A20="","",SUMIFS('Expense Source'!$M$5:$M$178,'Expense Source'!$D$5:$D$178,A20,'Expense Source'!$U$5:$U$178,1)) -> 106.63034 | G20: =IF(A20="","",IF(COUNTIFS('Income Source'!$B$5:$B$65,A20)=0,"",IF($Q$3="All",SUMIFS('Income Source'!$G$5:$G$65,'Income Source'!$B$5:$B$65,A20),SUM(B20:D20)))) -> 1089 | H20: =IF(A20="","",IF(COUNTIFS('Income Source'!$B$5:$B$65,A20)=0,"",G20-F20)) -> 982.36966 | I20: =IF(OR(A20="",COUNTIFS('Income Source'!$B$5:$B$65,A20)=0,G20=0),"",H20/G20) -> 0.90208417 | J20: =IF(A20="","",IF(COUNTIFS('Income Source'!$B$5:$B$65,A20)=0,"Revenue source missing",IF(ABS(E20-G20)>0.005,"Income/revenue mismatch","OK"))) -> OK | AB20: Karam Bake
A21: =IF($B$3="All",46208,IF(4<31,IF($B$3="July 2026",46204,46235)+4,"")) -> 46208 | B21: =IF(A21="","",IF(COUNTIFS('Income Source'!$B$5:$B$65,A21)=0,"",IF(OR($Q$3="All",$Q$3="Walk-in"),SUMIFS('Income Source'!$C$5:$C$65,'Income Source'!$B$5:$B$65,A21),0))) -> 241 | C21: =IF(A21="","",IF(COUNTIFS('Income Source'!$B$5:$B$65,A21)=0,"",IF(OR($Q$3="All",$Q$3="Colonie"),SUMIFS('Income Source'!$D$5:$D$65,'Income Source'!$B$5:$B$65,A21),0))) -> 0 | D21: =IF(A21="","",IF(COUNTIFS('Income Source'!$B$5:$B$65,A21)=0,"",IF(OR($Q$3="All",$Q$3="Birthday"),SUMIFS('Income Source'!$E$5:$E$65,'Income Source'!$B$5:$B$65,A21),0))) -> 750 | E21: =IF(A21="","",IF(COUNTIFS('Income Source'!$B$5:$B$65,A21)=0,"",SUM(B21:D21))) -> 991 | F21: =IF(A21="","",SUMIFS('Expense Source'!$M$5:$M$178,'Expense Source'!$D$5:$D$178,A21,'Expense Source'!$U$5:$U$178,1)) -> 510.71 | G21: =IF(A21="","",IF(COUNTIFS('Income Source'!$B$5:$B$65,A21)=0,"",IF($Q$3="All",SUMIFS('Income Source'!$G$5:$G$65,'Income Source'!$B$5:$B$65,A21),SUM(B21:D21)))) -> 991 | H21: =IF(A21="","",IF(COUNTIFS('Income Source'!$B$5:$B$65,A21)=0,"",G21-F21)) -> 480.29 | I21: =IF(OR(A21="",COUNTIFS('Income Source'!$B$5:$B$65,A21)=0,G21=0),"",H21/G21) -> 0.48465187 | J21: =IF(A21="","",IF(COUNTIFS('Income Source'!$B$5:$B$65,A21)=0,"Revenue source missing",IF(ABS(E21-G21)>0.005,"Income/revenue mismatch","OK"))) -> OK | AB21: La Valeur Market
A22: =IF($B$3="All",46209,IF(5<31,IF($B$3="July 2026",46204,46235)+5,"")) -> 46209 | B22: =IF(A22="","",IF(COUNTIFS('Income Source'!$B$5:$B$65,A22)=0,"",IF(OR($Q$3="All",$Q$3="Walk-in"),SUMIFS('Income Source'!$C$5:$C$65,'Income Source'!$B$5:$B$65,A22),0))) -> 0 | C22: =IF(A22="","",IF(COUNTIFS('Income Source'!$B$5:$B$65,A22)=0,"",IF(OR($Q$3="All",$Q$3="Colonie"),SUMIFS('Income Source'!$D$5:$D$65,'Income Source'!$B$5:$B$65,A22),0))) -> 0 | D22: =IF(A22="","",IF(COUNTIFS('Income Source'!$B$5:$B$65,A22)=0,"",IF(OR($Q$3="All",$Q$3="Birthday"),SUMIFS('Income Source'!$E$5:$E$65,'Income Source'!$B$5:$B$65,A22),0))) -> 0 | E22: =IF(A22="","",IF(COUNTIFS('Income Source'!$B$5:$B$65,A22)=0,"",SUM(B22:D22))) -> 0 | F22: =IF(A22="","",SUMIFS('Expense Source'!$M$5:$M$178,'Expense Source'!$D$5:$D$178,A22,'Expense Source'!$U$5:$U$178,1)) -> 0 | G22: =IF(A22="","",IF(COUNTIFS('Income Source'!$B$5:$B$65,A22)=0,"",IF($Q$3="All",SUMIFS('Income Source'!$G$5:$G$65,'Income Source'!$B$5:$B$65,A22),SUM(B22:D22)))) -> 0 | H22: =IF(A22="","",IF(COUNTIFS('Income Source'!$B$5:$B$65,A22)=0,"",G22-F22)) -> 0 | I22: =IF(OR(A22="",COUNTIFS('Income Source'!$B$5:$B$65,A22)=0,G22=0),"",H22/G22) | J22: =IF(A22="","",IF(COUNTIFS('Income Source'!$B$5:$B$65,A22)=0,"Revenue source missing",IF(ABS(E22-G22)>0.005,"Income/revenue mismatch","OK"))) -> OK | AB22: Le Charcutier
A23: =IF($B$3="All",46210,IF(6<31,IF($B$3="July 2026",46204,46235)+6,"")) -> 46210 | B23: =IF(A23="","",IF(COUNTIFS('Income Source'!$B$5:$B$65,A23)=0,"",IF(OR($Q$3="All",$Q$3="Walk-in"),SUMIFS('Income Source'!$C$5:$C$65,'Income Source'!$B$5:$B$65,A23),0))) -> 0 | C23: =IF(A23="","",IF(COUNTIFS('Income Source'!$B$5:$B$65,A23)=0,"",IF(OR($Q$3="All",$Q$3="Colonie"),SUMIFS('Income Source'!$D$5:$D$65,'Income Source'!$B$5:$B$65,A23),0))) -> 0 | D23: =IF(A23="","",IF(COUNTIFS('Income Source'!$B$5:$B$65,A23)=0,"",IF(OR($Q$3="All",$Q$3="Birthday"),SUMIFS('Income Source'!$E$5:$E$65,'Income Source'!$B$5:$B$65,A23),0))) -> 0 | E23: =IF(A23="","",IF(COUNTIFS('Income Source'!$B$5:$B$65,A23)=0,"",SUM(B23:D23))) -> 0 | F23: =IF(A23="","",SUMIFS('Expense Source'!$M$5:$M$178,'Expense Source'!$D$5:$D$178,A23,'Expense Source'!$U$5:$U$178,1)) -> 0 | G23: =IF(A23="","",IF(COUNTIFS('Income Source'!$B$5:$B$65,A23)=0,"",IF($Q$3="All",SUMIFS('Income Source'!$G$5:$G$65,'Income Source'!$B$5:$B$65,A23),SUM(B23:D23)))) -> 0 | H23: =IF(A23="","",IF(COUNTIFS('Income Source'!$B$5:$B$65,A23)=0,"",G23-F23)) -> 0 | I23: =IF(OR(A23="",COUNTIFS('Income Source'!$B$5:$B$65,A23)=0,G23=0),"",H23/G23) | J23: =IF(A23="","",IF(COUNTIFS('Income Source'!$B$5:$B$65,A23)=0,"Revenue source missing",IF(ABS(E23-G23)>0.005,"Income/revenue mismatch","OK"))) -> OK | AB23: Le Marche Selectif
A24: =IF($B$3="All",46211,IF(7<31,IF($B$3="July 2026",46204,46235)+7,"")) -> 46211 | B24: =IF(A24="","",IF(COUNTIFS('Income Source'!$B$5:$B$65,A24)=0,"",IF(OR($Q$3="All",$Q$3="Walk-in"),SUMIFS('Income Source'!$C$5:$C$65,'Income Source'!$B$5:$B$65,A24),0))) -> 0 | C24: =IF(A24="","",IF(COUNTIFS('Income Source'!$B$5:$B$65,A24)=0,"",IF(OR($Q$3="All",$Q$3="Colonie"),SUMIFS('Income Source'!$D$5:$D$65,'Income Source'!$B$5:$B$65,A24),0))) -> 760 | D24: =IF(A24="","",IF(COUNTIFS('Income Source'!$B$5:$B$65,A24)=0,"",IF(OR($Q$3="All",$Q$3="Birthday"),SUMIFS('Income Source'!$E$5:$E$65,'Income Source'!$B$5:$B$65,A24),0))) -> 625 | E24: =IF(A24="","",IF(COUNTIFS('Income Source'!$B$5:$B$65,A24)=0,"",SUM(B24:D24))) -> 1385 | F24: =IF(A24="","",SUMIFS('Expense Source'!$M$5:$M$178,'Expense Source'!$D$5:$D$178,A24,'Expense Source'!$U$5:$U$178,1)) -> 88.34 | G24: =IF(A24="","",IF(COUNTIFS('Income Source'!$B$5:$B$65,A24)=0,"",IF($Q$3="All",SUMIFS('Income Source'!$G$5:$G$65,'Income Source'!$B$5:$B$65,A24),SUM(B24:D24)))) -> 1385 | H24: =IF(A24="","",IF(COUNTIFS('Income Source'!$B$5:$B$65,A24)=0,"",G24-F24)) -> 1296.66 | I24: =IF(OR(A24="",COUNTIFS('Income Source'!$B$5:$B$65,A24)=0,G24=0),"",H24/G24) -> 0.93621661 | J24: =IF(A24="","",IF(COUNTIFS('Income Source'!$B$5:$B$65,A24)=0,"Revenue source missing",IF(ABS(E24-G24)>0.005,"Income/revenue mismatch","OK"))) -> OK | AB24: Librairie Mallah
A25: =IF($B$3="All",46212,IF(8<31,IF($B$3="July 2026",46204,46235)+8,"")) -> 46212 | B25: =IF(A25="","",IF(COUNTIFS('Income Source'!$B$5:$B$65,A25)=0,"",IF(OR($Q$3="All",$Q$3="Walk-in"),SUMIFS('Income Source'!$C$5:$C$65,'Income Source'!$B$5:$B$65,A25),0))) -> 0 | C25: =IF(A25="","",IF(COUNTIFS('Income Source'!$B$5:$B$65,A25)=0,"",IF(OR($Q$3="All",$Q$3="Colonie"),SUMIFS('Income Source'!$D$5:$D$65,'Income Source'!$B$5:$B$65,A25),0))) -> 528 | D25: =IF(A25="","",IF(COUNTIFS('Income Source'!$B$5:$B$65,A25)=0,"",IF(OR($Q$3="All",$Q$3="Birthday"),SUMIFS('Income Source'!$E$5:$E$65,'Income Source'!$B$5:$B$65,A25),0))) -> 0 | E25: =IF(A25="","",IF(COUNTIFS('Income Source'!$B$5:$B$65,A25)=0,"",SUM(B25:D25))) -> 528 | F25: =IF(A25="","",SUMIFS('Expense Source'!$M$5:$M$178,'Expense Source'!$D$5:$D$178,A25,'Expense Source'!$U$5:$U$178,1)) -> 0 | G25: =IF(A25="","",IF(COUNTIFS('Income Source'!$B$5:$B$65,A25)=0,"",IF($Q$3="All",SUMIFS('Income Source'!$G$5:$G$65,'Income Source'!$B$5:$B$65,A25),SUM(B25:D25)))) -> 528 | H25: =IF(A25="","",IF(COUNTIFS('Income Source'!$B$5:$B$65,A25)=0,"",G25-F25)) -> 528 | I25: =IF(OR(A25="",COUNTIFS('Income Source'!$B$5:$B$65,A25)=0,G25=0),"",H25/G25) -> 1 | J25: =IF(A25="","",IF(COUNTIFS('Income Source'!$B$5:$B$65,A25)=0,"Revenue source missing",IF(ABS(E25-G25)>0.005,"Income/revenue mismatch","OK"))) -> OK | AB25: Lteif Market
A26: =IF($B$3="All",46213,IF(9<31,IF($B$3="July 2026",46204,46235)+9,"")) -> 46213 | B26: =IF(A26="","",IF(COUNTIFS('Income Source'!$B$5:$B$65,A26)=0,"",IF(OR($Q$3="All",$Q$3="Walk-in"),SUMIFS('Income Source'!$C$5:$C$65,'Income Source'!$B$5:$B$65,A26),0))) -> 0 | C26: =IF(A26="","",IF(COUNTIFS('Income Source'!$B$5:$B$65,A26)=0,"",IF(OR($Q$3="All",$Q$3="Colonie"),SUMIFS('Income Source'!$D$5:$D$65,'Income Source'!$B$5:$B$65,A26),0))) -> 384 | D26: =IF(A26="","",IF(COUNTIFS('Income Source'!$B$5:$B$65,A26)=0,"",IF(OR($Q$3="All",$Q$3="Birthday"),SUMIFS('Income Source'!$E$5:$E$65,'Income Source'!$B$5:$B$65,A26),0))) -> 755 | E26: =IF(A26="","",IF(COUNTIFS('Income Source'!$B$5:$B$65,A26)=0,"",SUM(B26:D26))) -> 1139 | F26: =IF(A26="","",SUMIFS('Expense Source'!$M$5:$M$178,'Expense Source'!$D$5:$D$178,A26,'Expense Source'!$U$5:$U$178,1)) -> 625.79 | G26: =IF(A26="","",IF(COUNTIFS('Income Source'!$B$5:$B$65,A26)=0,"",IF($Q$3="All",SUMIFS('Income Source'!$G$5:$G$65,'Income Source'!$B$5:$B$65,A26),SUM(B26:D26)))) -> 1139 | H26: =IF(A26="","",IF(COUNTIFS('Income Source'!$B$5:$B$65,A26)=0,"",G26-F26)) -> 513.21 | I26: =IF(OR(A26="",COUNTIFS('Income Source'!$B$5:$B$65,A26)=0,G26=0),"",H26/G26) -> 0.45057946 | J26: =IF(A26="","",IF(COUNTIFS('Income Source'!$B$5:$B$65,A26)=0,"Revenue source missing",IF(ABS(E26-G26)>0.005,"Income/revenue mismatch","OK"))) -> OK | AB26: Luicci
A27: =IF($B$3="All",46214,IF(10<31,IF($B$3="July 2026",46204,46235)+10,"")) -> 46214 | B27: =IF(A27="","",IF(COUNTIFS('Income Source'!$B$5:$B$65,A27)=0,"",IF(OR($Q$3="All",$Q$3="Walk-in"),SUMIFS('Income Source'!$C$5:$C$65,'Income Source'!$B$5:$B$65,A27),0))) -> 453 | C27: =IF(A27="","",IF(COUNTIFS('Income Source'!$B$5:$B$65,A27)=0,"",IF(OR($Q$3="All",$Q$3="Colonie"),SUMIFS('Income Source'!$D$5:$D$65,'Income Source'!$B$5:$B$65,A27),0))) -> 0 | D27: =IF(A27="","",IF(COUNTIFS('Income Source'!$B$5:$B$65,A27)=0,"",IF(OR($Q$3="All",$Q$3="Birthday"),SUMIFS('Income Source'!$E$5:$E$65,'Income Source'!$B$5:$B$65,A27),0))) -> 1335 | E27: =IF(A27="","",IF(COUNTIFS('Income Source'!$B$5:$B$65,A27)=0,"",SUM(B27:D27))) -> 1788 | F27: =IF(A27="","",SUMIFS('Expense Source'!$M$5:$M$178,'Expense Source'!$D$5:$D$178,A27,'Expense Source'!$U$5:$U$178,1)) -> 182.25 | G27: =IF(A27="","",IF(COUNTIFS('Income Source'!$B$5:$B$65,A27)=0,"",IF($Q$3="All",SUMIFS('Income Source'!$G$5:$G$65,'Income Source'!$B$5:$B$65,A27),SUM(B27:D27)))) -> 1788 | H27: =IF(A27="","",IF(COUNTIFS('Income Source'!$B$5:$B$65,A27)=0,"",G27-F27)) -> 1605.75 | I27: =IF(OR(A27="",COUNTIFS('Income Source'!$B$5:$B$65,A27)=0,G27=0),"",H27/G27) -> 0.89807047 | J27: =IF(A27="","",IF(COUNTIFS('Income Source'!$B$5:$B$65,A27)=0,"Revenue source missing",IF(ABS(E27-G27)>0.005,"Income/revenue mismatch","OK"))) -> OK | AB27: Panino Bakery
A28: =IF($B$3="All",46215,IF(11<31,IF($B$3="July 2026",46204,46235)+11,"")) -> 46215 | B28: =IF(A28="","",IF(COUNTIFS('Income Source'!$B$5:$B$65,A28)=0,"",IF(OR($Q$3="All",$Q$3="Walk-in"),SUMIFS('Income Source'!$C$5:$C$65,'Income Source'!$B$5:$B$65,A28),0))) -> 370 | C28: =IF(A28="","",IF(COUNTIFS('Income Source'!$B$5:$B$65,A28)=0,"",IF(OR($Q$3="All",$Q$3="Colonie"),SUMIFS('Income Source'!$D$5:$D$65,'Income Source'!$B$5:$B$65,A28),0))) -> 0 | D28: =IF(A28="","",IF(COUNTIFS('Income Source'!$B$5:$B$65,A28)=0,"",IF(OR($Q$3="All",$Q$3="Birthday"),SUMIFS('Income Source'!$E$5:$E$65,'Income Source'!$B$5:$B$65,A28),0))) -> 550 | E28: =IF(A28="","",IF(COUNTIFS('Income Source'!$B$5:$B$65,A28)=0,"",SUM(B28:D28))) -> 920 | F28: =IF(A28="","",SUMIFS('Expense Source'!$M$5:$M$178,'Expense Source'!$D$5:$D$178,A28,'Expense Source'!$U$5:$U$178,1)) -> 193.1964 | G28: =IF(A28="","",IF(COUNTIFS('Income Source'!$B$5:$B$65,A28)=0,"",IF($Q$3="All",SUMIFS('Income Source'!$G$5:$G$65,'Income Source'!$B$5:$B$65,A28),SUM(B28:D28)))) -> 920 | H28: =IF(A28="","",IF(COUNTIFS('Income Source'!$B$5:$B$65,A28)=0,"",G28-F28)) -> 726.8036 | I28: =IF(OR(A28="",COUNTIFS('Income Source'!$B$5:$B$65,A28)=0,G28=0),"",H28/G28) -> 0.79000391 | J28: =IF(A28="","",IF(COUNTIFS('Income Source'!$B$5:$B$65,A28)=0,"Revenue source missing",IF(ABS(E28-G28)>0.005,"Income/revenue mismatch","OK"))) -> OK | AB28: Polavera
A29: =IF($B$3="All",46216,IF(12<31,IF($B$3="July 2026",46204,46235)+12,"")) -> 46216 | B29: =IF(A29="","",IF(COUNTIFS('Income Source'!$B$5:$B$65,A29)=0,"",IF(OR($Q$3="All",$Q$3="Walk-in"),SUMIFS('Income Source'!$C$5:$C$65,'Income Source'!$B$5:$B$65,A29),0))) -> 0 | C29: =IF(A29="","",IF(COUNTIFS('Income Source'!$B$5:$B$65,A29)=0,"",IF(OR($Q$3="All",$Q$3="Colonie"),SUMIFS('Income Source'!$D$5:$D$65,'Income Source'!$B$5:$B$65,A29),0))) -> 0 | D29: =IF(A29="","",IF(COUNTIFS('Income Source'!$B$5:$B$65,A29)=0,"",IF(OR($Q$3="All",$Q$3="Birthday"),SUMIFS('Income Source'!$E$5:$E$65,'Income Source'!$B$5:$B$65,A29),0))) -> 0 | E29: =IF(A29="","",IF(COUNTIFS('Income Source'!$B$5:$B$65,A29)=0,"",SUM(B29:D29))) -> 0 | F29: =IF(A29="","",SUMIFS('Expense Source'!$M$5:$M$178,'Expense Source'!$D$5:$D$178,A29,'Expense Source'!$U$5:$U$178,1)) -> 0 | G29: =IF(A29="","",IF(COUNTIFS('Income Source'!$B$5:$B$65,A29)=0,"",IF($Q$3="All",SUMIFS('Income Source'!$G$5:$G$65,'Income Source'!$B$5:$B$65,A29),SUM(B29:D29)))) -> 0 | H29: =IF(A29="","",IF(COUNTIFS('Income Source'!$B$5:$B$65,A29)=0,"",G29-F29)) -> 0 | I29: =IF(OR(A29="",COUNTIFS('Income Source'!$B$5:$B$65,A29)=0,G29=0),"",H29/G29) | J29: =IF(A29="","",IF(COUNTIFS('Income Source'!$B$5:$B$65,A29)=0,"Revenue source missing",IF(ABS(E29-G29)>0.005,"Income/revenue mismatch","OK"))) -> OK | AB29: Ramel Mgharbal, Trabeh
A30: =IF($B$3="All",46217,IF(13<31,IF($B$3="July 2026",46204,46235)+13,"")) -> 46217 | B30: =IF(A30="","",IF(COUNTIFS('Income Source'!$B$5:$B$65,A30)=0,"",IF(OR($Q$3="All",$Q$3="Walk-in"),SUMIFS('Income Source'!$C$5:$C$65,'Income Source'!$B$5:$B$65,A30),0))) -> 0 | C30: =IF(A30="","",IF(COUNTIFS('Income Source'!$B$5:$B$65,A30)=0,"",IF(OR($Q$3="All",$Q$3="Colonie"),SUMIFS('Income Source'!$D$5:$D$65,'Income Source'!$B$5:$B$65,A30),0))) -> 0 | D30: =IF(A30="","",IF(COUNTIFS('Income Source'!$B$5:$B$65,A30)=0,"",IF(OR($Q$3="All",$Q$3="Birthday"),SUMIFS('Income Source'!$E$5:$E$65,'Income Source'!$B$5:$B$65,A30),0))) -> 0 | E30: =IF(A30="","",IF(COUNTIFS('Income Source'!$B$5:$B$65,A30)=0,"",SUM(B30:D30))) -> 0 | F30: =IF(A30="","",SUMIFS('Expense Source'!$M$5:$M$178,'Expense Source'!$D$5:$D$178,A30,'Expense Source'!$U$5:$U$178,1)) -> 0 | G30: =IF(A30="","",IF(COUNTIFS('Income Source'!$B$5:$B$65,A30)=0,"",IF($Q$3="All",SUMIFS('Income Source'!$G$5:$G$65,'Income Source'!$B$5:$B$65,A30),SUM(B30:D30)))) -> 0 | H30: =IF(A30="","",IF(COUNTIFS('Income Source'!$B$5:$B$65,A30)=0,"",G30-F30)) -> 0 | I30: =IF(OR(A30="",COUNTIFS('Income Source'!$B$5:$B$65,A30)=0,G30=0),"",H30/G30) | J30: =IF(A30="","",IF(COUNTIFS('Income Source'!$B$5:$B$65,A30)=0,"Revenue source missing",IF(ABS(E30-G30)>0.005,"Income/revenue mismatch","OK"))) -> OK | AB30: Rim Water
A31: =IF($B$3="All",46218,IF(14<31,IF($B$3="July 2026",46204,46235)+14,"")) -> 46218 | B31: =IF(A31="","",IF(COUNTIFS('Income Source'!$B$5:$B$65,A31)=0,"",IF(OR($Q$3="All",$Q$3="Walk-in"),SUMIFS('Income Source'!$C$5:$C$65,'Income Source'!$B$5:$B$65,A31),0))) -> 0 | C31: =IF(A31="","",IF(COUNTIFS('Income Source'!$B$5:$B$65,A31)=0,"",IF(OR($Q$3="All",$Q$3="Colonie"),SUMIFS('Income Source'!$D$5:$D$65,'Income Source'!$B$5:$B$65,A31),0))) -> 0 | D31: =IF(A31="","",IF(COUNTIFS('Income Source'!$B$5:$B$65,A31)=0,"",IF(OR($Q$3="All",$Q$3="Birthday"),SUMIFS('Income Source'!$E$5:$E$65,'Income Source'!$B$5:$B$65,A31),0))) -> 0 | E31: =IF(A31="","",IF(COUNTIFS('Income Source'!$B$5:$B$65,A31)=0,"",SUM(B31:D31))) -> 0 | F31: =IF(A31="","",SUMIFS('Expense Source'!$M$5:$M$178,'Expense Source'!$D$5:$D$178,A31,'Expense Source'!$U$5:$U$178,1)) -> 0 | G31: =IF(A31="","",IF(COUNTIFS('Income Source'!$B$5:$B$65,A31)=0,"",IF($Q$3="All",SUMIFS('Income Source'!$G$5:$G$65,'Income Source'!$B$5:$B$65,A31),SUM(B31:D31)))) -> 0 | H31: =IF(A31="","",IF(COUNTIFS('Income Source'!$B$5:$B$65,A31)=0,"",G31-F31)) -> 0 | I31: =IF(OR(A31="",COUNTIFS('Income Source'!$B$5:$B$65,A31)=0,G31=0),"",H31/G31) | J31: =IF(A31="","",IF(COUNTIFS('Income Source'!$B$5:$B$65,A31)=0,"Revenue source missing",IF(ABS(E31-G31)>0.005,"Income/revenue mismatch","OK"))) -> OK | AB31: Spinneys
A32: =IF($B$3="All",46219,IF(15<31,IF($B$3="July 2026",46204,46235)+15,"")) -> 46219 | B32: =IF(A32="","",IF(COUNTIFS('Income Source'!$B$5:$B$65,A32)=0,"",IF(OR($Q$3="All",$Q$3="Walk-in"),SUMIFS('Income Source'!$C$5:$C$65,'Income Source'!$B$5:$B$65,A32),0))) -> 0 | C32: =IF(A32="","",IF(COUNTIFS('Income Source'!$B$5:$B$65,A32)=0,"",IF(OR($Q$3="All",$Q$3="Colonie"),SUMIFS('Income Source'!$D$5:$D$65,'Income Source'!$B$5:$B$65,A32),0))) -> 0 | D32: =IF(A32="","",IF(COUNTIFS('Income Source'!$B$5:$B$65,A32)=0,"",IF(OR($Q$3="All",$Q$3="Birthday"),SUMIFS('Income Source'!$E$5:$E$65,'Income Source'!$B$5:$B$65,A32),0))) -> 0 | E32: =IF(A32="","",IF(COUNTIFS('Income Source'!$B$5:$B$65,A32)=0,"",SUM(B32:D32))) -> 0 | F32: =IF(A32="","",SUMIFS('Expense Source'!$M$5:$M$178,'Expense Source'!$D$5:$D$178,A32,'Expense Source'!$U$5:$U$178,1)) -> 0 | G32: =IF(A32="","",IF(COUNTIFS('Income Source'!$B$5:$B$65,A32)=0,"",IF($Q$3="All",SUMIFS('Income Source'!$G$5:$G$65,'Income Source'!$B$5:$B$65,A32),SUM(B32:D32)))) -> 0 | H32: =IF(A32="","",IF(COUNTIFS('Income Source'!$B$5:$B$65,A32)=0,"",G32-F32)) -> 0 | I32: =IF(OR(A32="",COUNTIFS('Income Source'!$B$5:$B$65,A32)=0,G32=0),"",H32/G32) | J32: =IF(A32="","",IF(COUNTIFS('Income Source'!$B$5:$B$65,A32)=0,"Revenue source missing",IF(ABS(E32-G32)>0.005,"Income/revenue mismatch","OK"))) -> OK | AB32: St Joseph Pharmacy
A33: =IF($B$3="All",46220,IF(16<31,IF($B$3="July 2026",46204,46235)+16,"")) -> 46220 | B33: =IF(A33="","",IF(COUNTIFS('Income Source'!$B$5:$B$65,A33)=0,"",IF(OR($Q$3="All",$Q$3="Walk-in"),SUMIFS('Income Source'!$C$5:$C$65,'Income Source'!$B$5:$B$65,A33),0))) -> 284 | C33: =IF(A33="","",IF(COUNTIFS('Income Source'!$B$5:$B$65,A33)=0,"",IF(OR($Q$3="All",$Q$3="Colonie"),SUMIFS('Income Source'!$D$5:$D$65,'Income Source'!$B$5:$B$65,A33),0))) -> 0 | D33: =IF(A33="","",IF(COUNTIFS('Income Source'!$B$5:$B$65,A33)=0,"",IF(OR($Q$3="All",$Q$3="Birthday"),SUMIFS('Income Source'!$E$5:$E$65,'Income Source'!$B$5:$B$65,A33),0))) -> 520 | E33: =IF(A33="","",IF(COUNTIFS('Income Source'!$B$5:$B$65,A33)=0,"",SUM(B33:D33))) -> 804 | F33: =IF(A33="","",SUMIFS('Expense Source'!$M$5:$M$178,'Expense Source'!$D$5:$D$178,A33,'Expense Source'!$U$5:$U$178,1)) -> 732.31 | G33: =IF(A33="","",IF(COUNTIFS('Income Source'!$B$5:$B$65,A33)=0,"",IF($Q$3="All",SUMIFS('Income Source'!$G$5:$G$65,'Income Source'!$B$5:$B$65,A33),SUM(B33:D33)))) -> 804 | H33: =IF(A33="","",IF(COUNTIFS('Income Source'!$B$5:$B$65,A33)=0,"",G33-F33)) -> 71.69 | I33: =IF(OR(A33="",COUNTIFS('Income Source'!$B$5:$B$65,A33)=0,G33=0),"",H33/G33) -> 0.089166667 | J33: =IF(A33="","",IF(COUNTIFS('Income Source'!$B$5:$B$65,A33)=0,"Revenue source missing",IF(ABS(E33-G33)>0.005,"Income/revenue mismatch","OK"))) -> OK | AB33: Storium
A34: =IF($B$3="All",46221,IF(17<31,IF($B$3="July 2026",46204,46235)+17,"")) -> 46221 | B34: =IF(A34="","",IF(COUNTIFS('Income Source'!$B$5:$B$65,A34)=0,"",IF(OR($Q$3="All",$Q$3="Walk-in"),SUMIFS('Income Source'!$C$5:$C$65,'Income Source'!$B$5:$B$65,A34),0))) -> 330 | C34: =IF(A34="","",IF(COUNTIFS('Income Source'!$B$5:$B$65,A34)=0,"",IF(OR($Q$3="All",$Q$3="Colonie"),SUMIFS('Income Source'!$D$5:$D$65,'Income Source'!$B$5:$B$65,A34),0))) -> 0 | D34: =IF(A34="","",IF(COUNTIFS('Income Source'!$B$5:$B$65,A34)=0,"",IF(OR($Q$3="All",$Q$3="Birthday"),SUMIFS('Income Source'!$E$5:$E$65,'Income Source'!$B$5:$B$65,A34),0))) -> 1150 | E34: =IF(A34="","",IF(COUNTIFS('Income Source'!$B$5:$B$65,A34)=0,"",SUM(B34:D34))) -> 1480 | F34: =IF(A34="","",SUMIFS('Expense Source'!$M$5:$M$178,'Expense Source'!$D$5:$D$178,A34,'Expense Source'!$U$5:$U$178,1)) -> 218.049 | G34: =IF(A34="","",IF(COUNTIFS('Income Source'!$B$5:$B$65,A34)=0,"",IF($Q$3="All",SUMIFS('Income Source'!$G$5:$G$65,'Income Source'!$B$5:$B$65,A34),SUM(B34:D34)))) -> 1480 | H34: =IF(A34="","",IF(COUNTIFS('Income Source'!$B$5:$B$65,A34)=0,"",G34-F34)) -> 1261.951 | I34: =IF(OR(A34="",COUNTIFS('Income Source'!$B$5:$B$65,A34)=0,G34=0),"",H34/G34) -> 0.85266959 | J34: =IF(A34="","",IF(COUNTIFS('Income Source'!$B$5:$B$65,A34)=0,"Revenue source missing",IF(ABS(E34-G34)>0.005,"Income/revenue mismatch","OK"))) -> OK | AB34: Sunrise Market
A35: =IF($B$3="All",46222,IF(18<31,IF($B$3="July 2026",46204,46235)+18,"")) -> 46222 | B35: =IF(A35="","",IF(COUNTIFS('Income Source'!$B$5:$B$65,A35)=0,"",IF(OR($Q$3="All",$Q$3="Walk-in"),SUMIFS('Income Source'!$C$5:$C$65,'Income Source'!$B$5:$B$65,A35),0))) -> 77 | C35: =IF(A35="","",IF(COUNTIFS('Income Source'!$B$5:$B$65,A35)=0,"",IF(OR($Q$3="All",$Q$3="Colonie"),SUMIFS('Income Source'!$D$5:$D$65,'Income Source'!$B$5:$B$65,A35),0))) -> 0 | D35: =IF(A35="","",IF(COUNTIFS('Income Source'!$B$5:$B$65,A35)=0,"",IF(OR($Q$3="All",$Q$3="Birthday"),SUMIFS('Income Source'!$E$5:$E$65,'Income Source'!$B$5:$B$65,A35),0))) -> 525 | E35: =IF(A35="","",IF(COUNTIFS('Income Source'!$B$5:$B$65,A35)=0,"",SUM(B35:D35))) -> 602 | F35: =IF(A35="","",SUMIFS('Expense Source'!$M$5:$M$178,'Expense Source'!$D$5:$D$178,A35,'Expense Source'!$U$5:$U$178,1)) -> 124.49543 | G35: =IF(A35="","",IF(COUNTIFS('Income Source'!$B$5:$B$65,A35)=0,"",IF($Q$3="All",SUMIFS('Income Source'!$G$5:$G$65,'Income Source'!$B$5:$B$65,A35),SUM(B35:D35)))) -> 602 | H35: =IF(A35="","",IF(COUNTIFS('Income Source'!$B$5:$B$65,A35)=0,"",G35-F35)) -> 477.50457 | I35: =IF(OR(A35="",COUNTIFS('Income Source'!$B$5:$B$65,A35)=0,G35=0),"",H35/G35) -> 0.79319697 | J35: =IF(A35="","",IF(COUNTIFS('Income Source'!$B$5:$B$65,A35)=0,"Revenue source missing",IF(ABS(E35-G35)>0.005,"Income/revenue mismatch","OK"))) -> OK | AB35: Toni Nehme
A36: =IF($B$3="All",46223,IF(19<31,IF($B$3="July 2026",46204,46235)+19,"")) -> 46223 | B36: =IF(A36="","",IF(COUNTIFS('Income Source'!$B$5:$B$65,A36)=0,"",IF(OR($Q$3="All",$Q$3="Walk-in"),SUMIFS('Income Source'!$C$5:$C$65,'Income Source'!$B$5:$B$65,A36),0))) -> 0 | C36: =IF(A36="","",IF(COUNTIFS('Income Source'!$B$5:$B$65,A36)=0,"",IF(OR($Q$3="All",$Q$3="Colonie"),SUMIFS('Income Source'!$D$5:$D$65,'Income Source'!$B$5:$B$65,A36),0))) -> 0 | D36: =IF(A36="","",IF(COUNTIFS('Income Source'!$B$5:$B$65,A36)=0,"",IF(OR($Q$3="All",$Q$3="Birthday"),SUMIFS('Income Source'!$E$5:$E$65,'Income Source'!$B$5:$B$65,A36),0))) -> 0 | E36: =IF(A36="","",IF(COUNTIFS('Income Source'!$B$5:$B$65,A36)=0,"",SUM(B36:D36))) -> 0 | F36: =IF(A36="","",SUMIFS('Expense Source'!$M$5:$M$178,'Expense Source'!$D$5:$D$178,A36,'Expense Source'!$U$5:$U$178,1)) -> 45.39 | G36: =IF(A36="","",IF(COUNTIFS('Income Source'!$B$5:$B$65,A36)=0,"",IF($Q$3="All",SUMIFS('Income Source'!$G$5:$G$65,'Income Source'!$B$5:$B$65,A36),SUM(B36:D36)))) -> 0 | H36: =IF(A36="","",IF(COUNTIFS('Income Source'!$B$5:$B$65,A36)=0,"",G36-F36)) -> -45.39 | I36: =IF(OR(A36="",COUNTIFS('Income Source'!$B$5:$B$65,A36)=0,G36=0),"",H36/G36) | J36: =IF(A36="","",IF(COUNTIFS('Income Source'!$B$5:$B$65,A36)=0,"Revenue source missing",IF(ABS(E36-G36)>0.005,"Income/revenue mismatch","OK"))) -> OK | AB36: Toni Tohme Station
A37: =IF($B$3="All",46224,IF(20<31,IF($B$3="July 2026",46204,46235)+20,"")) -> 46224 | B37: =IF(A37="","",IF(COUNTIFS('Income Source'!$B$5:$B$65,A37)=0,"",IF(OR($Q$3="All",$Q$3="Walk-in"),SUMIFS('Income Source'!$C$5:$C$65,'Income Source'!$B$5:$B$65,A37),0))) -> 0 | C37: =IF(A37="","",IF(COUNTIFS('Income Source'!$B$5:$B$65,A37)=0,"",IF(OR($Q$3="All",$Q$3="Colonie"),SUMIFS('Income Source'!$D$5:$D$65,'Income Source'!$B$5:$B$65,A37),0))) -> 0 | D37: =IF(A37="","",IF(COUNTIFS('Income Source'!$B$5:$B$65,A37)=0,"",IF(OR($Q$3="All",$Q$3="Birthday"),SUMIFS('Income Source'!$E$5:$E$65,'Income Source'!$B$5:$B$65,A37),0))) -> 0 | E37: =IF(A37="","",IF(COUNTIFS('Income Source'!$B$5:$B$65,A37)=0,"",SUM(B37:D37))) -> 0 | F37: =IF(A37="","",SUMIFS('Expense Source'!$M$5:$M$178,'Expense Source'!$D$5:$D$178,A37,'Expense Source'!$U$5:$U$178,1)) -> 0 | G37: =IF(A37="","",IF(COUNTIFS('Income Source'!$B$5:$B$65,A37)=0,"",IF($Q$3="All",SUMIFS('Income Source'!$G$5:$G$65,'Income Source'!$B$5:$B$65,A37),SUM(B37:D37)))) -> 0 | H37: =IF(A37="","",IF(COUNTIFS('Income Source'!$B$5:$B$65,A37)=0,"",G37-F37)) -> 0 | I37: =IF(OR(A37="",COUNTIFS('Income Source'!$B$5:$B$65,A37)=0,G37=0),"",H37/G37) | J37: =IF(A37="","",IF(COUNTIFS('Income Source'!$B$5:$B$65,A37)=0,"Revenue source missing",IF(ABS(E37-G37)>0.005,"Income/revenue mismatch","OK"))) -> OK | AB37: Unspecified
A38: =IF($B$3="All",46225,IF(21<31,IF($B$3="July 2026",46204,46235)+21,"")) -> 46225 | B38: =IF(A38="","",IF(COUNTIFS('Income Source'!$B$5:$B$65,A38)=0,"",IF(OR($Q$3="All",$Q$3="Walk-in"),SUMIFS('Income Source'!$C$5:$C$65,'Income Source'!$B$5:$B$65,A38),0))) -> 0 | C38: =IF(A38="","",IF(COUNTIFS('Income Source'!$B$5:$B$65,A38)=0,"",IF(OR($Q$3="All",$Q$3="Colonie"),SUMIFS('Income Source'!$D$5:$D$65,'Income Source'!$B$5:$B$65,A38),0))) -> 660 | D38: =IF(A38="","",IF(COUNTIFS('Income Source'!$B$5:$B$65,A38)=0,"",IF(OR($Q$3="All",$Q$3="Birthday"),SUMIFS('Income Source'!$E$5:$E$65,'Income Source'!$B$5:$B$65,A38),0))) -> 0 | E38: =IF(A38="","",IF(COUNTIFS('Income Source'!$B$5:$B$65,A38)=0,"",SUM(B38:D38))) -> 660 | F38: =IF(A38="","",SUMIFS('Expense Source'!$M$5:$M$178,'Expense Source'!$D$5:$D$178,A38,'Expense Source'!$U$5:$U$178,1)) -> 0 | G38: =IF(A38="","",IF(COUNTIFS('Income Source'!$B$5:$B$65,A38)=0,"",IF($Q$3="All",SUMIFS('Income Source'!$G$5:$G$65,'Income Source'!$B$5:$B$65,A38),SUM(B38:D38)))) -> 660 | H38: =IF(A38="","",IF(COUNTIFS('Income Source'!$B$5:$B$65,A38)=0,"",G38-F38)) -> 660 | I38: =IF(OR(A38="",COUNTIFS('Income Source'!$B$5:$B$65,A38)=0,G38=0),"",H38/G38) -> 1 | J38: =IF(A38="","",IF(COUNTIFS('Income Source'!$B$5:$B$65,A38)=0,"Revenue source missing",IF(ABS(E38-G38)>0.005,"Income/revenue mismatch","OK"))) -> OK | AB38: Youssef Malek
A39: =IF($B$3="All",46226,IF(22<31,IF($B$3="July 2026",46204,46235)+22,"")) -> 46226 | B39: =IF(A39="","",IF(COUNTIFS('Income Source'!$B$5:$B$65,A39)=0,"",IF(OR($Q$3="All",$Q$3="Walk-in"),SUMIFS('Income Source'!$C$5:$C$65,'Income Source'!$B$5:$B$65,A39),0))) -> 0 | C39: =IF(A39="","",IF(COUNTIFS('Income Source'!$B$5:$B$65,A39)=0,"",IF(OR($Q$3="All",$Q$3="Colonie"),SUMIFS('Income Source'!$D$5:$D$65,'Income Source'!$B$5:$B$65,A39),0))) -> 0 | D39: =IF(A39="","",IF(COUNTIFS('Income Source'!$B$5:$B$65,A39)=0,"",IF(OR($Q$3="All",$Q$3="Birthday"),SUMIFS('Income Source'!$E$5:$E$65,'Income Source'!$B$5:$B$65,A39),0))) -> 0 | E39: =IF(A39="","",IF(COUNTIFS('Income Source'!$B$5:$B$65,A39)=0,"",SUM(B39:D39))) -> 0 | F39: =IF(A39="","",SUMIFS('Expense Source'!$M$5:$M$178,'Expense Source'!$D$5:$D$178,A39,'Expense Source'!$U$5:$U$178,1)) -> 93.51 | G39: =IF(A39="","",IF(COUNTIFS('Income Source'!$B$5:$B$65,A39)=0,"",IF($Q$3="All",SUMIFS('Income Source'!$G$5:$G$65,'Income Source'!$B$5:$B$65,A39),SUM(B39:D39)))) -> 0 | H39: =IF(A39="","",IF(COUNTIFS('Income Source'!$B$5:$B$65,A39)=0,"",G39-F39)) -> -93.51 | I39: =IF(OR(A39="",COUNTIFS('Income Source'!$B$5:$B$65,A39)=0,G39=0),"",H39/G39) | J39: =IF(A39="","",IF(COUNTIFS('Income Source'!$B$5:$B$65,A39)=0,"Revenue source missing",IF(ABS(E39-G39)>0.005,"Income/revenue mismatch","OK"))) -> OK
A40: =IF($B$3="All",46227,IF(23<31,IF($B$3="July 2026",46204,46235)+23,"")) -> 46227 | B40: =IF(A40="","",IF(COUNTIFS('Income Source'!$B$5:$B$65,A40)=0,"",IF(OR($Q$3="All",$Q$3="Walk-in"),SUMIFS('Income Source'!$C$5:$C$65,'Income Source'!$B$5:$B$65,A40),0))) -> 228 | C40: =IF(A40="","",IF(COUNTIFS('Income Source'!$B$5:$B$65,A40)=0,"",IF(OR($Q$3="All",$Q$3="Colonie"),SUMIFS('Income Source'!$D$5:$D$65,'Income Source'!$B$5:$B$65,A40),0))) -> 0 | D40: =IF(A40="","",IF(COUNTIFS('Income Source'!$B$5:$B$65,A40)=0,"",IF(OR($Q$3="All",$Q$3="Birthday"),SUMIFS('Income Source'!$E$5:$E$65,'Income Source'!$B$5:$B$65,A40),0))) -> 450 | E40: =IF(A40="","",IF(COUNTIFS('Income Source'!$B$5:$B$65,A40)=0,"",SUM(B40:D40))) -> 678 | F40: =IF(A40="","",SUMIFS('Expense Source'!$M$5:$M$178,'Expense Source'!$D$5:$D$178,A40,'Expense Source'!$U$5:$U$178,1)) -> 348.93438 | G40: =IF(A40="","",IF(COUNTIFS('Income Source'!$B$5:$B$65,A40)=0,"",IF($Q$3="All",SUMIFS('Income Source'!$G$5:$G$65,'Income Source'!$B$5:$B$65,A40),SUM(B40:D40)))) -> 678 | H40: =IF(A40="","",IF(COUNTIFS('Income Source'!$B$5:$B$65,A40)=0,"",G40-F40)) -> 329.06562 | I40: =IF(OR(A40="",COUNTIFS('Income Source'!$B$5:$B$65,A40)=0,G40=0),"",H40/G40) -> 0.48534752 | J40: =IF(A40="","",IF(COUNTIFS('Income Source'!$B$5:$B$65,A40)=0,"Revenue source missing",IF(ABS(E40-G40)>0.005,"Income/revenue mismatch","OK"))) -> OK
...

Sheet Income Source
A1: M - July & August Income Source
A4: Source Sheet | B4: Date | C4: Walk-in | D4: Colonie | E4: Birthday | F4: Source Daily Expenses | G4: Source Revenue | H4: Source Check
A5: July | B5: 46205 | C5: 0 | D5: 520 | E5: 0 | G5: 520 | H5: =IF(ABS(G5-(SUM(C5:E5)-F5))<0.005,"OK","Check") -> OK
A6: July | B6: 46206 | C6: 0 | D6: 0 | E6: 434 | G6: 434 | H6: =IF(ABS(G6-(SUM(C6:E6)-F6))<0.005,"OK","Check") -> OK
A7: July | B7: 46207 | C7: 238 | D7: 100 | E7: 751 | G7: 1089 | H7: =IF(ABS(G7-(SUM(C7:E7)-F7))<0.005,"OK","Check") -> OK
A8: July | B8: 46208 | C8: 241 | D8: 0 | E8: 750 | G8: 991 | H8: =IF(ABS(G8-(SUM(C8:E8)-F8))<0.005,"OK","Check") -> OK
A9: July | B9: 46209 | G9: 0 | H9: =IF(ABS(G9-(SUM(C9:E9)-F9))<0.005,"OK","Check") -> OK
A10: July | B10: 46210 | G10: 0 | H10: =IF(ABS(G10-(SUM(C10:E10)-F10))<0.005,"OK","Check") -> OK
A11: July | B11: 46211 | D11: 760 | E11: 625 | G11: 1385 | H11: =IF(ABS(G11-(SUM(C11:E11)-F11))<0.005,"OK","Check") -> OK
A12: July | B12: 46212 | D12: 528 | G12: 528 | H12: =IF(ABS(G12-(SUM(C12:E12)-F12))<0.005,"OK","Check") -> OK
A13: July | B13: 46213 | D13: 384 | E13: 755 | G13: 1139 | H13: =IF(ABS(G13-(SUM(C13:E13)-F13))<0.005,"OK","Check") -> OK
A14: July | B14: 46214 | C14: 453 | E14: 1335 | G14: 1788 | H14: =IF(ABS(G14-(SUM(C14:E14)-F14))<0.005,"OK","Check") -> OK
A15: July | B15: 46215 | C15: 370 | E15: 550 | G15: 920 | H15: =IF(ABS(G15-(SUM(C15:E15)-F15))<0.005,"OK","Check") -> OK
A16: July | B16: 46216 | G16: 0 | H16: =IF(ABS(G16-(SUM(C16:E16)-F16))<0.005,"OK","Check") -> OK
A17: July | B17: 46217 | G17: 0 | H17: =IF(ABS(G17-(SUM(C17:E17)-F17))<0.005,"OK","Check") -> OK
A18: July | B18: 46218 | G18: 0 | H18: =IF(ABS(G18-(SUM(C18:E18)-F18))<0.005,"OK","Check") -> OK
A19: July | B19: 46219 | G19: 0 | H19: =IF(ABS(G19-(SUM(C19:E19)-F19))<0.005,"OK","Check") -> OK
A20: July | B20: 46220 | C20: 284 | E20: 520 | G20: 804 | H20: =IF(ABS(G20-(SUM(C20:E20)-F20))<0.005,"OK","Check") -> OK
A21: July | B21: 46221 | C21: 330 | E21: 1150 | G21: 1480 | H21: =IF(ABS(G21-(SUM(C21:E21)-F21))<0.005,"OK","Check") -> OK
A22: July | B22: 46222 | C22: 77 | E22: 525 | G22: 602 | H22: =IF(ABS(G22-(SUM(C22:E22)-F22))<0.005,"OK","Check") -> OK
A23: July | B23: 46223 | G23: 0 | H23: =IF(ABS(G23-(SUM(C23:E23)-F23))<0.005,"OK","Check") -> OK
A24: July | B24: 46224 | G24: 0 | H24: =IF(ABS(G24-(SUM(C24:E24)-F24))<0.005,"OK","Check") -> OK
A25: July | B25: 46225 | D25: 660 | G25: 660 | H25: =IF(ABS(G25-(SUM(C25:E25)-F25))<0.005,"OK","Check") -> OK
A26: July | B26: 46226 | G26: 0 | H26: =IF(ABS(G26-(SUM(C26:E26)-F26))<0.005,"OK","Check") -> OK
A27: July | B27: 46227 | C27: 228 | E27: 450 | G27: 678 | H27: =IF(ABS(G27-(SUM(C27:E27)-F27))<0.005,"OK","Check") -> OK
A28: July | B28: 46228 | C28: 191 | E28: 650 | G28: 841 | H28: =IF(ABS(G28-(SUM(C28:E28)-F28))<0.005,"OK","Check") -> OK
A29: July | B29: 46229 | E29: 1690 | G29: 1690 | H29: =IF(ABS(G29-(SUM(C29:E29)-F29))<0.005,"OK","Check") -> OK
A30: July | B30: 46230 | E30: 1477 | G30: 1477 | H30: =IF(ABS(G30-(SUM(C30:E30)-F30))<0.005,"OK","Check") -> OK
A31: July | B31: 46231 | C31: 0 | D31: 204 | G31: 204 | H31: =IF(ABS(G31-(SUM(C31:E31)-F31))<0.005,"OK","Check") -> OK
A32: July | B32: 46232 | E32: 950 | G32: 950 | H32: =IF(ABS(G32-(SUM(C32:E32)-F32))<0.005,"OK","Check") -> OK
A33: July | B33: 46233 | D33: 228 | G33: 228 | H33: =IF(ABS(G33-(SUM(C33:E33)-F33))<0.005,"OK","Check") -> OK
A34: July | B34: 46234 | C34: 166 | D34: 336 | E34: 185 | G34: 687 | H34: =IF(ABS(G34-(SUM(C34:E34)-F34))<0.005,"OK","Check") -> OK
A35: August | B35: 46235 | C35: 250 | D35: 0 | E35: 945 | G35: 1195 | H35: =IF(ABS(G35-(SUM(C35:E35)-F35))<0.005,"OK","Check") -> OK
A36: August | B36: 46236 | C36: 785 | D36: 0 | E36: 0 | G36: 785 | H36: =IF(ABS(G36-(SUM(C36:E36)-F36))<0.005,"OK","Check") -> OK
A37: August | B37: 46237 | C37: 0 | D37: 0 | E37: 0 | G37: 0 | H37: =IF(ABS(G37-(SUM(C37:E37)-F37))<0.005,"OK","Check") -> OK
A38: August | B38: 46238 | C38: 0 | D38: 0 | E38: 0 | G38: 0 | H38: =IF(ABS(G38-(SUM(C38:E38)-F38))<0.005,"OK","Check") -> OK
A39: August | B39: 46239 | C39: 0 | D39: 388 | G39: 388 | H39: =IF(ABS(G39-(SUM(C39:E39)-F39))<0.005,"OK","Check") -> OK
A40: August | B40: 46240 | C40: 0 | D40: 372 | G40: 372 | H40: =IF(ABS(G40-(SUM(C40:E40)-F40))<0.005,"OK","Check") -> OK
A41: August | B41: 46241 | C41: 0 | D41: 0 | E41: 0 | G41: 0 | H41: =IF(ABS(G41-(SUM(C41:E41)-F41))<0.005,"OK","Check") -> OK
A42: August | B42: 46242 | C42: 250 | D42: 950 | E42: 0 | G42: 1200 | H42: =IF(ABS(G42-(SUM(C42:E42)-F42))<0.005,"OK","Check") -> OK
...

Sheet Expense Source
A1: M - Corrected Expense Source
A4: Expense ID | B4: Source Bill Key | C4: Source Invoice No. | D4: Date | E4: Month | F4: Activity Tags | G4: Activity Detail | H4: Source Category | I4: Expense Category | J4: Expense Type | K4: Supplier | L4: Description | M4: Amount USD | N4: Amount LBP | O4: Effective FX | P4: Source Sheet | Q4: Source Rows | R4: Review Flag | S4: Selected Flag | T4: Selected Bill Flag | U4: Profitability Flag
A5: 20260630-001 | B5: 20260630-001 | C5: 0 | D5: 46203 | E5: June 2026 | F5: Workshop | G5: Oui Oui Nursery Workshops | H5: Librairie | I5: Workshop & Decoration Supplies | J5: Decoration & Workshop Materials | K5: Librairie Mallah | L5: Divers | M5: 152.5 | N5: 0 | P5: 30- June | Q5: 4-7 | R5: Outside July period | S5: 0 | T5: 0 | U5: =IF(AND(OR('Daily Profitability'!$E$3="All",ISNUMBER(SEARCH('Daily Profitability'!$E$3,F5))),OR('Daily Profitability'!$H$3="All",I5='Daily Profitability'!$H$3),OR('Daily Profitability'!$K$3="All",J5='Daily Profitability'!$K$3),OR('Daily Profitability'!$N$3="All",K5='Daily Profitability'!$N$3)),1,0) -> 0
A6: 20260630-002 | B6: 20260630-002 | C6: Unrecorded | D6: 46203 | E6: June 2026 | F6: Workshop | G6: Oui Oui Nursery Workshops | H6: Office Expenses | I6: Utilities & Office | J6: Maintenance | K6: Unspecified | L6: Moteur June | M6: 295 | N6: 0 | P6: 30- June | Q6: 10 | R6: Supplier not recorded; outside July period | S6: 0 | T6: 0 | U6: =IF(AND(OR('Daily Profitability'!$E$3="All",ISNUMBER(SEARCH('Daily Profitability'!$E$3,F6))),OR('Daily Profitability'!$H$3="All",I6='Daily Profitability'!$H$3),OR('Daily Profitability'!$K$3="All",J6='Daily Profitability'!$K$3),OR('Daily Profitability'!$N$3="All",K6='Daily Profitability'!$N$3)),1,0) -> 0
A7: 20260704-001 | B7: 20260704-001 | C7: Unrecorded | D7: 46207 | E7: July 2026 | F7: Birthday | G7: Birthday & Burger Workshops Barbecue | H7: Garbage | I7: Cleaning & Waste | J7: Waste Removal | K7: Imaco | L7: Description not recorded | M7: 30 | N7: 0 | P7: 4- July | Q7: 4 | R7: OK | S7: 0 | T7: 0 | U7: =IF(AND(OR('Daily Profitability'!$E$3="All",ISNUMBER(SEARCH('Daily Profitability'!$E$3,F7))),OR('Daily Profitability'!$H$3="All",I7='Daily Profitability'!$H$3),OR('Daily Profitability'!$K$3="All",J7='Daily Profitability'!$K$3),OR('Daily Profitability'!$N$3="All",K7='Daily Profitability'!$N$3)),1,0) -> 0
A8: 20260704-002 | B8: 20260704-002 | C8: Unrecorded | D8: 46207 | E8: July 2026 | F8: Birthday | G8: Birthday & Burger Workshops Barbecue | H8: Kitchen | I8: Food & Beverage | J8: Food & Beverage | K8: Forn Zakhia | L8: Manakich | M8: 5.7303371 | N8: 510000 | O8: 89000 | P8: 4- July | Q8: 6 | R8: OK | S8: 0 | T8: 0 | U8: =IF(AND(OR('Daily Profitability'!$E$3="All",ISNUMBER(SEARCH('Daily Profitability'!$E$3,F8))),OR('Daily Profitability'!$H$3="All",I8='Daily Profitability'!$H$3),OR('Daily Profitability'!$K$3="All",J8='Daily Profitability'!$K$3),OR('Daily Profitability'!$N$3="All",K8='Daily Profitability'!$N$3)),1,0) -> 1
A9: 20260704-003 | B9: 20260704-003 | C9: 0 | D9: 46207 | E9: July 2026 | F9: Birthday | G9: Birthday & Burger Workshops Barbecue | H9: Kitchen | I9: Food & Beverage | J9: Food & Beverage | K9: Le Marche Selectif | L9: F&V, Ice,Mozarella,Sugar | M9: 100.9 | N9: 0 | P9: 4- July | Q9: 7 | R9: OK | S9: 0 | T9: 0 | U9: =IF(AND(OR('Daily Profitability'!$E$3="All",ISNUMBER(SEARCH('Daily Profitability'!$E$3,F9))),OR('Daily Profitability'!$H$3="All",I9='Daily Profitability'!$H$3),OR('Daily Profitability'!$K$3="All",J9='Daily Profitability'!$K$3),OR('Daily Profitability'!$N$3="All",K9='Daily Profitability'!$N$3)),1,0) -> 1
A10: 20260704-004 | B10: 20260704-004 | C10: Unrecorded | D10: 46207 | E10: July 2026 | F10: Birthday | G10: Birthday & Burger Workshops Barbecue | H10: Office Expenses | I10: Utilities & Office | J10: Water | K10: Toni Tohme Station | L10: Water Citern | M10: 80 | N10: 0 | P10: 4- July | Q10: 9 | R10: OK | S10: 0 | T10: 0 | U10: =IF(AND(OR('Daily Profitability'!$E$3="All",ISNUMBER(SEARCH('Daily Profitability'!$E$3,F10))),OR('Daily Profitability'!$H$3="All",I10='Daily Profitability'!$H$3),OR('Daily Profitability'!$K$3="All",J10='Daily Profitability'!$K$3),OR('Daily Profitability'!$N$3="All",K10='Daily Profitability'!$N$3)),1,0) -> 0
A11: 20260704-005 | B11: 20260704-005 | C11: 0 | D11: 46207 | E11: July 2026 | F11: Birthday | G11: Birthday & Burger Workshops Barbecue | H11: Office Expenses | I11: Utilities & Office | J11: Electricity | K11: EDL | L11: Electricity | M11: 51.08 | N11: 0 | P11: 4- July | Q11: 10 | R11: OK | S11: 0 | T11: 0 | U11: =IF(AND(OR('Daily Profitability'!$E$3="All",ISNUMBER(SEARCH('Daily Profitability'!$E$3,F11))),OR('Daily Profitability'!$H$3="All",I11='Daily Profitability'!$H$3),OR('Daily Profitability'!$K$3="All",J11='Daily Profitability'!$K$3),OR('Daily Profitability'!$N$3="All",K11='Daily Profitability'!$N$3)),1,0) -> 0
A12: 20260704-006 | B12: 20260704-006 | C12: Unrecorded | D12: 46207 | E12: July 2026 | F12: Birthday | G12: Birthday & Burger Workshops Barbecue | H12: Workshops | I12: Workshop & Decoration Supplies | J12: Decoration & Workshop Materials | K12: Spinneys | L12: Divers | M12: 37.27 | N12: 0 | P12: 4- July | Q12: 12 | R12: OK | S12: 0 | T12: 0 | U12: =IF(AND(OR('Daily Profitability'!$E$3="All",ISNUMBER(SEARCH('Daily Profitability'!$E$3,F12))),OR('Daily Profitability'!$H$3="All",I12='Daily Profitability'!$H$3),OR('Daily Profitability'!$K$3="All",J12='Daily Profitability'!$K$3),OR('Daily Profitability'!$N$3="All",K12='Daily Profitability'!$N$3)),1,0) -> 0
A13: 20260704-007 | B13: 20260704-007 | C13: 0 | D13: 46207 | E13: July 2026 | F13: Birthday | G13: Birthday & Burger Workshops Barbecue | H13: Workshops | I13: Workshop & Decoration Supplies | J13: Decoration & Workshop Materials | K13: Event Megastore | L13: Description not recorded | M13: 32.31 | N13: 0 | P13: 4- July | Q13: 13 | R13: OK | S13: 0 | T13: 0 | U13: =IF(AND(OR('Daily Profitability'!$E$3="All",ISNUMBER(SEARCH('Daily Profitability'!$E$3,F13))),OR('Daily Profitability'!$H$3="All",I13='Daily Profitability'!$H$3),OR('Daily Profitability'!$K$3="All",J13='Daily Profitability'!$K$3),OR('Daily Profitability'!$N$3="All",K13='Daily Profitability'!$N$3)),1,0) -> 0
A14: 20260705-001 | B14: 20260705-001 | C14: 0 | D14: 46208 | E14: July 2026 | F14: Birthday | G14: Birthday | H14: Kitchen | I14: Food & Beverage | J14: Food & Beverage | K14: Le Marche Selectif | L14: Fruits & Vegetables; Fahem Colomby; Water Rim Box of 2 litre | M14: 41.3 | N14: 0 | P14: 5-July | Q14: 3-5 | R14: OK | S14: 0 | T14: 0 | U14: =IF(AND(OR('Daily Profitability'!$E$3="All",ISNUMBER(SEARCH('Daily Profitability'!$E$3,F14))),OR('Daily Profitability'!$H$3="All",I14='Daily Profitability'!$H$3),OR('Daily Profitability'!$K$3="All",J14='Daily Profitability'!$K$3),OR('Daily Profitability'!$N$3="All",K14='Daily Profitability'!$N$3)),1,0) -> 1
A15: 20260705-002 | B15: 20260705-002 | C15: 0 | D15: 46208 | E15: July 2026 | F15: Birthday | G15: Birthday | H15: Kitchen | I15: Food & Beverage | J15: Food & Beverage | K15: Storium | L15: Balkis | M15: 28.79 | N15: 0 | P15: 5-July | Q15: 6 | R15: OK | S15: 0 | T15: 0 | U15: =IF(AND(OR('Daily Profitability'!$E$3="All",ISNUMBER(SEARCH('Daily Profitability'!$E$3,F15))),OR('Daily Profitability'!$H$3="All",I15='Daily Profitability'!$H$3),OR('Daily Profitability'!$K$3="All",J15='Daily Profitability'!$K$3),OR('Daily Profitability'!$N$3="All",K15='Daily Profitability'!$N$3)),1,0) -> 1
A16: 20260705-003 | B16: 20260705-003 | C16: 0 | D16: 46208 | E16: July 2026 | F16: Birthday | G16: Birthday | H16: Kitchen | I16: Food & Beverage | J16: Food & Beverage | K16: Le Marche Selectif | L16: Ice, F&v Vinigar, Olive Black, cheese,Chicken Breast, Fa7em Mozarella | M16: 177.87 | N16: 0 | P16: 5-July | Q16: 7 | R16: OK | S16: 0 | T16: 0 | U16: =IF(AND(OR('Daily Profitability'!$E$3="All",ISNUMBER(SEARCH('Daily Profitability'!$E$3,F16))),OR('Daily Profitability'!$H$3="All",I16='Daily Profitability'!$H$3),OR('Daily Profitability'!$K$3="All",J16='Daily Profitability'!$K$3),OR('Daily Profitability'!$N$3="All",K16='Daily Profitability'!$N$3)),1,0) -> 1
A17: 20260705-004 | B17: 20260705-004 | C17: 0 | D17: 46208 | E17: July 2026 | F17: Birthday | G17: Birthday | H17: Kitchen | I17: Food & Beverage | J17: Food & Beverage | K17: Spinneys | L17: Brasilian Beef & Prunell; Beer,Milk, Wipes, Cacao | M17: 199.47 | N17: 0 | P17: 5-July | Q17: 8-9 | R17: OK | S17: 0 | T17: 0 | U17: =IF(AND(OR('Daily Profitability'!$E$3="All",ISNUMBER(SEARCH('Daily Profitability'!$E$3,F17))),OR('Daily Profitability'!$H$3="All",I17='Daily Profitability'!$H$3),OR('Daily Profitability'!$K$3="All",J17='Daily Profitability'!$K$3),OR('Daily Profitability'!$N$3="All",K17='Daily Profitability'!$N$3)),1,0) -> 1
A18: 20260705-005 | B18: 20260705-005 | C18: 0 | D18: 46208 | E18: July 2026 | F18: Birthday | G18: Birthday | H18: Kitchen | I18: Food & Beverage | J18: Food & Beverage | K18: Karam Bake | L18: Description not recorded | M18: 63.28 | N18: 0 | P18: 5-July | Q18: 10 | R18: OK | S18: 0 | T18: 0 | U18: =IF(AND(OR('Daily Profitability'!$E$3="All",ISNUMBER(SEARCH('Daily Profitability'!$E$3,F18))),OR('Daily Profitability'!$H$3="All",I18='Daily Profitability'!$H$3),OR('Daily Profitability'!$K$3="All",J18='Daily Profitability'!$K$3),OR('Daily Profitability'!$N$3="All",K18='Daily Profitability'!$N$3)),1,0) -> 1
A19: 20260708-001 | B19: 20260708-001 | C19: Unrecorded | D19: 46211 | E19: July 2026 | F19: Birthday | G19: Birthday | H19: Office Expenses | I19: Utilities & Office | J19: Maintenance | K19: Ets Melhem Yamine & Sons | L19: Industrial Walls | M19: 160 | N19: 0 | P19: 8-July | Q19: 3 | R19: OK | S19: 0 | T19: 0 | U19: =IF(AND(OR('Daily Profitability'!$E$3="All",ISNUMBER(SEARCH('Daily Profitability'!$E$3,F19))),OR('Daily Profitability'!$H$3="All",I19='Daily Profitability'!$H$3),OR('Daily Profitability'!$K$3="All",J19='Daily Profitability'!$K$3),OR('Daily Profitability'!$N$3="All",K19='Daily Profitability'!$N$3)),1,0) -> 0
A20: 20260708-002 | B20: 20260708-002 | C20: Unrecorded | D20: 46211 | E20: July 2026 | F20: Birthday | G20: Birthday | H20: Workshops | I20: Workshop & Decoration Supplies | J20: Decoration & Workshop Materials | K20: Librairie Mallah | L20: Divers | M20: 18 | N20: 0 | P20: 8-July | Q20: 5 | R20: OK | S20: 0 | T20: 0 | U20: =IF(AND(OR('Daily Profitability'!$E$3="All",ISNUMBER(SEARCH('Daily Profitability'!$E$3,F20))),OR('Daily Profitability'!$H$3="All",I20='Daily Profitability'!$H$3),OR('Daily Profitability'!$K$3="All",J20='Daily Profitability'!$K$3),OR('Daily Profitability'!$N$3="All",K20='Daily Profitability'!$N$3)),1,0) -> 0
... A43: 20260712-003 | B43: 20260712-003 | C43: 0 | D43: 46215 | E43: July 2026 | F43: Unspecified | G43: No activity label recorded | H43: Kitchen | I43: Food & Beverage | J43: Food & Beverage | K43: Storium | L43: Fresh Juice Balkis | M43: 22.49 | N43: 0 | P43: July-12 | Q43: 5 | R43: OK | S43: 0 | T43: 0 | U43: =IF(AND(OR('Daily Profitability'!$E$3="All",ISNUMBER(SEARCH('Daily Profitability'!$E$3,F43))),OR('Daily Profitability'!$H$3="All",I43='Daily Profitability'!$H$3),OR('Daily Profitability'!$K$3="All",J43='Daily Profitability'!$K$3),OR('Daily Profitability'!$N$3="All",K43='Daily Profitability'!$N$3)),1,0) -> 1
A44: 20260712-004 | B44: 20260712-004 | C44: 0 | D44: 46215 | E44: July 2026 | F44: Unspecified | G44: No activity label recorded | H44: Kitchen | I44: Food & Beverage | J44: Food & Beverage | K44: Le Marche Selectif | L44: FRuit& Vege; Rim Water; Cold Ice; Labneh Khoury; tea; Persil; Bread White; Javel; Laban; Mozarella Wraped | M44: 84.076404 | N44: 7482800 | O44: 89000 | P44: July-12 | Q44: 7-16 | R44: OK | S44: 0 | T44: 0 | U44: =IF(AND(OR('Daily Profitability'!$E$3="All",ISNUMBER(SEARCH('Daily Profitability'!$E$3,F44))),OR('Daily Profitability'!$H$3="All",I44='Daily Profitability'!$H$3),OR('Daily Profitability'!$K$3="All",J44='Daily Profitability'!$K$3),OR('Daily Profitability'!$N$3="All",K44='Daily Profitability'!$N$3)),1,0) -> 1
A45: 20260712-005 | B45: 20260712-005 | C45: 0 | D45: 46215 | E45: July 2026 | F45: Unspecified | G45: No activity label recorded | H45: Kitchen | I45: Food & Beverage | J45: Food & Beverage | K45: Storium | L45: Cotton Wipes,Balkis Penne,Flowe | M45: 56.63 | N45: 0 | P45: July-12 | Q45: 17 | R45: OK | S45: 0 | T45: 0 | U45: =IF(AND(OR('Daily Profitability'!$E$3="All",ISNUMBER(SEARCH('Daily Profitability'!$E$3,F45))),OR('Daily Profitability'!$H$3="All",I45='Daily Profitability'!$H$3),OR('Daily Profitability'!$K$3="All",J45='Daily Profitability'!$K$3),OR('Daily Profitability'!$N$3="All",K45='Daily Profitability'!$N$3)),1,0) -> 1
A46: 20260712-006 | B46: 20260712-006 | C46: 0 | D46: 46215 | E46: July 2026 | F46: Unspecified | G46: No activity label recorded | H46: Workshops | I46: Workshop & Decoration Supplies | J46: Decoration & Workshop Materials | K46: Event Megastore | L46: Papier Crepon | M46: 5.1573034 | N46: 459000 | O46: 89000 | P46: July-12 | Q46: 25-26 | R46: OK | S46: 0 | T46: 0 | U46: =IF(AND(OR('Daily Profitability'!$E$3="All",ISNUMBER(SEARCH('Daily Profitability'!$E$3,F46))),OR('Daily Profitability'!$H$3="All",I46='Daily Profitability'!$H$3),OR('Daily Profitability'!$K$3="All",J46='Daily Profitability'!$K$3),OR('Daily Profitability'!$N$3="All",K46='Daily Profitability'!$N$3)),1,0) -> 0
A47: 20260712-007 | B47: 20260712-007 | C47: 0 | D47: 46215 | E47: July 2026 | F47: Unspecified | G47: No activity label recorded | H47: Workshops | I47: Workshop & Decoration Supplies | J47: Decoration & Workshop Materials | K47: Fairco International | L47: Wood Board | M47: 83.36 | N47: 0 | P47: July-12 | Q47: 30 | R47: OK | S47: 0 | T47: 0 | U47: =IF(AND(OR('Daily Profitability'!$E$3="All",ISNUMBER(SEARCH('Daily Profitability'!$E$3,F47))),OR('Daily Profitability'!$H$3="All",I47='Daily Profitability'!$H$3),OR('Daily Profitability'!$K$3="All",J47='Daily Profitability'!$K$3),OR('Daily Profitability'!$N$3="All",K47='Daily Profitability'!$N$3)),1,0) -> 0
A48: 20260717-001 | B48: 20260717-001 | C48: Unrecorded | D48: 46220 | E48: July 2026 | F48: Birthday | G48: Birthday | H48: Kitchen | I48: Food & Beverage | J48: Food & Beverage | K48: Karam Bake | L48: Mou3ajanet | M48: 51.33 | N48: 0 | P48: 17-July | Q48: 3 | R48: OK | S48: 0 | T48: 0 | U48: =IF(AND(OR('Daily Profitability'!$E$3="All",ISNUMBER(SEARCH('Daily Profitability'!$E$3,F48))),OR('Daily Profitability'!$H$3="All",I48='Daily Profitability'!$H$3),OR('Daily Profitability'!$K$3="All",J48='Daily Profitability'!$K$3),OR('Daily Profitability'!$N$3="All",K48='Daily Profitability'!$N$3)),1,0) -> 1
A49: 20260717-002 | B49: 20260717-002 | C49: 0 | D49: 46220 | E49: July 2026 | F49: Birthday | G49: Birthday | H49: Kitchen | I49: Food & Beverage | J49: Food & Beverage | K49: Spinneys | L49: Beirut Beer; Oui Oui Wipes; Rim Sparkling Water; Rim Sparkling Water Can; Domo Becarbonate sada; Domo Food Coloring; Sanita Classic; Souplex Powder; Sanita Zipper Bags; Quinoa; Vermicelle Pasta; Plein Soleil Tuna Oil; Sweet Corn; Pasta Fusilli; Extra Olive Oil; Adam Salt Fine; Origano spice; Mayonaise; Balsamic Vinegair; Ketchup Gallon 2 k; Tortillas; Devon Cheddar Chips; Croco Sticks; Croco Mix; Bjorg Choco Noir; Fruits & Vgtebales; Mozarella; President; Olive Slice; Aroma Pickles; Argal Pechuga; Ferrarini Padano | M49: 374.71 | N49: 27850538 | O49: 74325.58 | P49: 17-July | Q49: 5-36 | R49: OK | S49: 0 | T49: 0 | U49: =IF(AND(OR('Daily Profitability'!$E$3="All",ISNUMBER(SEARCH('Daily Profitability'!$E$3,F49))),OR('Daily Profitability'!$H$3="All",I49='Daily Profitability'!$H$3),OR('Daily Profitability'!$K$3="All",J49='Daily Profitability'!$K$3),OR('Daily Profitability'!$N$3="All",K49='Daily Profitability'!$N$3)),1,0) -> 1
A50: 20260717-003 | B50: 20260717-003 | C50: 0 | D50: 46220 | E50: July 2026 | F50: Birthday | G50: Birthday | H50: Workshops | I50: Workshop & Decoration Supplies | J50: Decoration & Workshop Materials | K50: Librairie Mallah | L50: Clay; Printing LAser,Clay,Peinture | M50: 92 | N50: 0 | P50: 17-July | Q50: 38-39 | R50: OK | S50: 0 | T50: 0 | U50: =IF(AND(OR('Daily Profitability'!$E$3="All",ISNUMBER(SEARCH('Daily Profitability'!$E$3,F50))),OR('Daily Profitability'!$H$3="All",I50='Daily Profitability'!$H$3),OR('Daily Profitability'!$K$3="All",J50='Daily Profitability'!$K$3),OR('Daily Profitability'!$N$3="All",K50='Daily Profitability'!$N$3)),1,0) -> 0
A51: 20260717-004 | B51: 20260717-004 | C51: 0 | D51: 46220 | E51: July 2026 | F51: Birthday | G51: Birthday | H51: Kitchen | I51: Food & Beverage | J51: Food & Beverage | K51: La Valeur Market | L51: Bread; Block Chocolate; Divers; Lurpak; Dark Chocolat; Coffe; Raisin Dark; Onion; Green Paper; Sun Flower oil; Walnuts; Mozarella Cheese; Pomi Tomato; Khoury Laban | M51: 101.28 | N51: 9100231 | O51: 89852.202 | P51: 17-July | Q51: 41-55 | R51: OK | S51: 0 | T51: 0 | U51: =IF(AND(OR('Daily Profitability'!$E$3="All",ISNUMBER(SEARCH('Daily Profitability'!$E$3,F51))),OR('Daily Profitability'!$H$3="All",I51='Daily Profitability'!$H$3),OR('Daily Profitability'!$K$3="All",J51='Daily Profitability'!$K$3),OR('Daily Profitability'!$N$3="All",K51='Daily Profitability'!$N$3)),1,0) -> 1
A52: 20260717-005 | B52: 20260717-005 | C52: Unrecorded | D52: 46220 | E52: July 2026 | F52: Birthday | G52: Birthday | H52: Office Expenses | I52: Disposables & Packaging | J52: Packaging & Disposables | K52: Disposable | L52: Froks.spoon, Meal Box, Juice Btl,Salad Boat, Plates Boat, Paper Boats, jars | M52: 134.75 | N52: 0 | P52: 17-July | Q52: 57 | R52: OK | S52: 0 | T52: 0 | U52: =IF(AND(OR('Daily Profitability'!$E$3="All",ISNUMBER(SEARCH('Daily Profitability'!$E$3,F52))),OR('Daily Profitability'!$H$3="All",I52='Daily Profitability'!$H$3),OR('Daily Profitability'!$K$3="All",J52='Daily Profitability'!$K$3),OR('Daily Profitability'!$N$3="All",K52='Daily Profitability'!$N$3)),1,0) -> 0
A53: 20260717-006 | B53: 20260717-006 | C53: Unrecorded | D53: 46220 | E53: July 2026 | F53: Birthday | G53: Birthday | H53: Kitchen | I53: Food & Beverage | J53: Food & Beverage | K53: Le Marche Selectif | L53: Cold Ice, Water Gallon &Small btls, Fruits , veg,Olive Oil , Sanita | M53: 185.9 | N53: 0 | P53: 17-July | Q53: 59 | R53: OK | S53: 0 | T53: 0 | U53: =IF(AND(OR('Daily Profitability'!$E$3="All",ISNUMBER(SEARCH('Daily Profitability'!$E$3,F53))),OR('Daily Profitability'!$H$3="All",I53='Daily Profitability'!$H$3),OR('Daily Profitability'!$K$3="All",J53='Daily Profitability'!$K$3),OR('Daily Profitability'!$N$3="All",K53='Daily Profitability'!$N$3)),1,0) -> 1
A54: 20260717-007 | B54: 20260717-007 | C54: 0 | D54: 46220 | E54: July 2026 | F54: Birthday | G54: Birthday | H54: Kitchen | I54: Food & Beverage | J54: Food & Beverage | K54: Boucherie Ziad | L54: Mafroume | M54: 19.09 | N54: 0 | P54: 17-July | Q54: 60 | R54: OK | S54: 0 | T54: 0 | U54: =IF(AND(OR('Daily Profitability'!$E$3="All",ISNUMBER(SEARCH('Daily Profitability'!$E$3,F54))),OR('Daily Profitability'!$H$3="All",I54='Daily Profitability'!$H$3),OR('Daily Profitability'!$K$3="All",J54='Daily Profitability'!$K$3),OR('Daily Profitability'!$N$3="All",K54='Daily Profitability'!$N$3)),1,0) -> 1
